Workbook
Name hdrRowNum: '설정'!$H$5
Name hdrRow: INDEX(RAW!$A:$XFD,hdrRowNum,0)
Name hdrList: INDEX(RAW!$A:$XFD,hdrRowNum,1):INDEX(RAW!$A:$XFD,hdrRowNum,'_calc'!$Q$3)
Name colPer: '설정'!$H$9
Name dPer: INDEX(RAW!$A:$XFD,hdrRowNum+1,colPer):INDEX(RAW!$A:$XFD,1048576,colPer)
Name colCust: '설정'!$H$10
Name dCust: INDEX(RAW!$A:$XFD,hdrRowNum+1,colCust):INDEX(RAW!$A:$XFD,1048576,colCust)
Name colQty: '설정'!$H$11
Name dQty: INDEX(RAW!$A:$XFD,hdrRowNum+1,colQty):INDEX(RAW!$A:$XFD,1048576,colQty)
Name colAmt: '설정'!$H$12
Name dAmt: INDEX(RAW!$A:$XFD,hdrRowNum+1,colAmt):INDEX(RAW!$A:$XFD,1048576,colAmt)
Name colFlt1: '설정'!$H$22
Name dFlt1: INDEX(RAW!$A:$XFD,hdrRowNum+1,colFlt1):INDEX(RAW!$A:$XFD,1048576,colFlt1)
Name colFlt2: '설정'!$H$23
Name dFlt2: INDEX(RAW!$A:$XFD,hdrRowNum+1,colFlt2):INDEX(RAW!$A:$XFD,1048576,colFlt2)
Name colFlt3: '설정'!$H$24
Name dFlt3: INDEX(RAW!$A:$XFD,hdrRowNum+1,colFlt3):INDEX(RAW!$A:$XFD,1048576,colFlt3)
Name critFlt1: '설정'!$I$22
Name critFlt2: '설정'!$I$23
Name critFlt3: '설정'!$I$24
Name cyFrom: '설정'!$C$16
Name cyTo: '설정'!$D$16
Name pyFrom: '설정'!$C$18
Name pyTo: '설정'!$D$18
Name cyLabel: '설정'!$E$16
Name pyLabel: '설정'!$E$18
Name sortIdx: '설정'!$H$28
Name sortList: '_calc'!$Q$8:$Q$10
Name mapOK: '_calc'!$Q$5
Name dynNA: '_calc'!$Q$6
Name nComp: '_calc'!$Q$2
Name nList: '_calc'!$Q$4

Sheet 사용방법
B1: Realized Price (ASP) 전년 대비 분석 — 사용 방법
B2: 세일즈 데이터를 붙여넣으면 전체·업체별 ASP(매출액 ÷ 수량)를 전년과 비교합니다.
B4: 시작하기 — 3단계
B5: 1 | C5: RAW 시트에 붙여넣기 | D5: RAW 시트에서 Ctrl+A → Delete로 예시 데이터를 지운 뒤, 추출한 세일즈 데이터를 A1 셀에 헤더(열 이름) 포함 그대로 붙여넣습니다. 열이 많거나 순서가 달라도 괜찮습니다 — 필요한 열은 '헤더명'으로 찾아서 씁니다.
B6: 2 | C6: 설정 시트 노란 칸 입력 | D6: ② 열 매핑: 기간·업체·수량·매출액 헤더를 드롭다운에서 선택 / ③ 비교 기간: 당해 시작·종료 입력 (전년은 자동으로 1년 전) / ④ 필터: 사업부·제품군·통화 등으로 좁힐 때만 / ⑥ 데이터 점검이 모두 ✔ 인지 확인
B7: 3 | C7: 업체별 ASP 시트에서 확인 | D7: 맨 위 '전체' 행이 전체 ASP 전년 대비, 그 아래가 업체별입니다. 정렬 기준(매출액 / ASP 증감률)은 설정 ⑤에서 바꿀 수 있습니다.
B9: 계산 기준
C10: ASP | D10: 매출액 합계 ÷ 수량 합계 (기간·업체별로 먼저 합산한 뒤 나눔 = 수량 가중 평균 단가)
C11: ASP 증감 / 증감률 | D11: 당해 ASP − 전년 ASP / 당해 ASP ÷ 전년 ASP − 1
C12: 당해 비중 | D12: 업체 당해 매출액 ÷ 전체 당해 매출액
C13: 기간 판정 | D13: 기간 열 값이 [시작, 종료] 안에 드는 행만 합산 (날짜 · 연도 2026 · 연월 202609 숫자 모두 가능)
C14: 비고 | D14: 신규(전년 수량 없음) / 당해 수량 없음 → 해당 업체는 ASP 증감을 계산하지 않음
B16: 주의할 점
C17: • 수량 단위(KG / EA 등)나 통화가 섞여 있으면 ASP가 왜곡됩니다 → 설정 ④ 필터로 하나만 남기세요.
C18: • 업체 ASP 증감에는 '같은 제품의 가격 변화'와 '제품 믹스 변화'가 함께 들어 있습니다. 제품군별로 보려면 필터에 제품군을 지정하세요.
C19: • 반품(− 수량)과 단가 소급 정산(수량 0, 금액만 있는 행)도 그대로 합산됩니다 = 실제 실현 단가.
C20: • 날짜·숫자가 텍스트로 붙여넣어지면 합계에서 빠집니다 → 설정 ⑥ 데이터 점검에서 확인하세요.
C21: • 업체 목록 자동 생성에는 Excel 2021 또는 Microsoft 365가 필요합니다(UNIQUE 함수). 이전 버전은 설정 ⑥의 안내대로 업체 목록을 직접 붙여넣으세요.
C22: • 업체는 최대 3,000개까지 표시됩니다. 수식이 들어 있는 칸(흰색·회색)은 지우지 마세요.
B24: 표시 안내
C25: 입력 | D25: 노란 칸 = 직접 입력하거나 드롭다운에서 고르는 칸
C26: ▲ 1.2% | D26: 전년 대비 상승
C27: ▼ 1.2% | D27: 전년 대비 하락
C28: 자동 | D28: 회색 칸 = 자동 계산 (수정 불필요)

Sheet 업체별 ASP
B1: 업체별 Realized Price (ASP) — 전년 대비
B2: ="비교 기간 당해 "&cyLabel&" vs 전년 "&pyLabel&" | ASP = "&'설정'!$C$12&" ÷ "&'설정'!$C$11&" | 필터: "&'설정'!$C$25 -> 비교 기간 당해 2026.01.01 ~ 2026.09.30 vs 전년 2025.01.01 ~ 2025.09.30 | ASP = 순매출액 ÷ 판매수량 | 필터: 없음 (전체 데이터)
B3: ="데이터 점검: "&'설정'!$E$45&IF('설정'!$C$45=0,""," → [설정] 시트 ⑥ 데이터 점검을 확인하세요") -> 데이터 점검: ⚠ 1건 확인 필요 → [설정] 시트 ⑥ 데이터 점검을 확인하세요
B4: =IF(OR(I8="",J8=""),"전체 ASP: 계산할 수 없습니다 (설정 시트 확인)","전체 ASP 전년 "&TEXT(I8,"#,##0.00")&" → 당해 "&TEXT(J8,"#,##0.00")&" ("&IF(L8="","-",IF(L8>0,"▲ ",IF(L8<0,"▼ ",""))&TEXT(ABS(L8),"0.0%"))&")") -> 전체 ASP 전년 1,957.99 → 당해 2,037.43 (▲ 4.1%)
B6: No | C6: 업체 | D6: 매출액 | G6: 수량 | I6: ASP (매출액 ÷ 수량) | M6: 비고
D7: 전년 | E7: 당해 | F7: 당해 비중 | G7: 전년 | H7: 당해 | I7: 전년 | J7: 당해 | K7: 증감 | L7: 증감률
C8: 전체 | D8: =SUMIFS(dAmt,dPer,">="&pyFrom,dPer,"<="&pyTo,dAmt,">-1E+300",dFlt1,critFlt1,dFlt2,critFlt2,dFlt3,critFlt3) -> 3952732664 | E8: =SUMIFS(dAmt,dPer,">="&cyFrom,dPer,"<="&cyTo,dAmt,">-1E+300",dFlt1,critFlt1,dFlt2,critFlt2,dFlt3,critFlt3) -> 4608364811 | F8: =IF(E8=0,"",1) -> 1 | G8: =SUMIFS(dQty,dPer,">="&pyFrom,dPer,"<="&pyTo,dQty,">-1E+300",dFlt1,critFlt1,dFlt2,critFlt2,dFlt3,critFlt3) -> 2018775 | H8: =SUMIFS(dQty,dPer,">="&cyFrom,dPer,"<="&cyTo,dQty,">-1E+300",dFlt1,critFlt1,dFlt2,critFlt2,dFlt3,critFlt3) -> 2261850 | I8: =IF(OR(NOT(mapOK),G8=0),"",D8/G8) -> 1957.9857 | J8: =IF(OR(NOT(mapOK),H8=0),"",E8/H8) -> 2037.4317 | K8: =IF(OR(I8="",J8=""),"",J8-I8) -> 79.445924 | L8: =IF(OR(I8="",J8=""),"",IF(I8=0,"",J8/I8-1)) -> 0.040575333 | M8: =IF(AND(G8=0,H8=0),"수량 없음",IF(G8=0,"전년 수량 없음",IF(H8=0,"당해 수량 없음","")))
B9: =IF(ROW()-ROW($B$8)>nComp,"",ROW()-ROW($B$8)) -> 1 | C9: =IF($N9="","",INDEX('_calc'!$A$2:$A$3001,$N9)) -> Sinar Plastik (ID) | D9: =IF($N9="","",INDEX('_calc'!$C$2:$C$3001,$N9)) -> 421977654 | E9: =IF($N9="","",INDEX('_calc'!$D$2:$D$3001,$N9)) -> 398348378 | F9: =IF($N9="","",IF($E$8=0,"",E9/$E$8)) -> 0.086440287 | G9: =IF($N9="","",INDEX('_calc'!$E$2:$E$3001,$N9)) -> 253975 | H9: =IF($N9="","",INDEX('_calc'!$F$2:$F$3001,$N9)) -> 239600 | I9: =IF($N9="","",INDEX('_calc'!$H$2:$H$3001,$N9)) -> 1661.4929 | J9: =IF($N9="","",INDEX('_calc'!$I$2:$I$3001,$N9)) -> 1662.5558 | K9: =IF($N9="","",IF(OR(I9="",J9=""),"",J9-I9)) -> 1.0629555 | L9: =IF($N9="","",INDEX('_calc'!$J$2:$J$3001,$N9)) -> 0.00063975929 | M9: =IF($N9="","",IF(AND(G9=0,H9=0),"수량 없음",IF(G9=0,"신규 (전년 수량 없음)",IF(H9=0,"당해 수량 없음","")))) | N9: =IF($B9="","",MATCH($B9,'_calc'!$L$2:$L$3001,0)) -> 14
B10: =IF(ROW()-ROW($B$8)>nComp,"",ROW()-ROW($B$8)) -> 2 | C10: =IF($N10="","",INDEX('_calc'!$A$2:$A$3001,$N10)) -> 큰별코리아 | D10: =IF($N10="","",INDEX('_calc'!$C$2:$C$3001,$N10)) -> 290530624 | E10: =IF($N10="","",INDEX('_calc'!$D$2:$D$3001,$N10)) -> 381024971 | F10: =IF($N10="","",IF($E$8=0,"",E10/$E$8)) -> 0.082681165 | G10: =IF($N10="","",INDEX('_calc'!$E$2:$E$3001,$N10)) -> 202875 | H10: =IF($N10="","",INDEX('_calc'!$F$2:$F$3001,$N10)) -> 270000 | I10: =IF($N10="","",INDEX('_calc'!$H$2:$H$3001,$N10)) -> 1432.0672 | J10: =IF($N10="","",INDEX('_calc'!$I$2:$I$3001,$N10)) -> 1411.2036 | K10: =IF($N10="","",IF(OR(I10="",J10=""),"",J10-I10)) -> -20.863558 | L10: =IF($N10="","",INDEX('_calc'!$J$2:$J$3001,$N10)) -> -0.014568841 | M10: =IF($N10="","",IF(AND(G10=0,H10=0),"수량 없음",IF(G10=0,"신규 (전년 수량 없음)",IF(H10=0,"당해 수량 없음","")))) | N10: =IF($B10="","",MATCH($B10,'_calc'!$L$2:$L$3001,0)) -> 6
B11: =IF(ROW()-ROW($B$8)>nComp,"",ROW()-ROW($B$8)) -> 3 | C11: =IF($N11="","",INDEX('_calc'!$A$2:$A$3001,$N11)) -> 새봄플라스틱 | D11: =IF($N11="","",INDEX('_calc'!$C$2:$C$3001,$N11)) -> 202915490 | E11: =IF($N11="","",INDEX('_calc'!$D$2:$D$3001,$N11)) -> 350242959 | F11: =IF($N11="","",IF($E$8=0,"",E11/$E$8)) -> 0.07600157 | G11: =IF($N11="","",INDEX('_calc'!$E$2:$E$3001,$N11)) -> 84650 | H11: =IF($N11="","",INDEX('_calc'!$F$2:$F$3001,$N11)) -> 136300 | I11: =IF($N11="","",INDEX('_calc'!$H$2:$H$3001,$N11)) -> 2397.1115 | J11: =IF($N11="","",INDEX('_calc'!$I$2:$I$3001,$N11)) -> 2569.6475 | K11: =IF($N11="","",IF(OR(I11="",J11=""),"",J11-I11)) -> 172.53602 | L11: =IF($N11="","",INDEX('_calc'!$J$2:$J$3001,$N11)) -> 0.071976633 | M11: =IF($N11="","",IF(AND(G11=0,H11=0),"수량 없음",IF(G11=0,"신규 (전년 수량 없음)",IF(H11=0,"당해 수량 없음","")))) | N11: =IF($B11="","",MATCH($B11,'_calc'!$L$2:$L$3001,0)) -> 2
B12: =IF(ROW()-ROW($B$8)>nComp,"",ROW()-ROW($B$8)) -> 4 | C12: =IF($N12="","",INDEX('_calc'!$A$2:$A$3001,$N12)) -> 나래산업(주) | D12: =IF($N12="","",INDEX('_calc'!$C$2:$C$3001,$N12)) -> 261543968 | E12: =IF($N12="","",INDEX('_calc'!$D$2:$D$3001,$N12)) -> 331743492 | F12: =IF($N12="","",IF($E$8=0,"",E12/$E$8)) -> 0.071987246 | G12: =IF($N12="","",INDEX('_calc'!$E$2:$E$3001,$N12)) -> 173850 | H12: =IF($N12="","",INDEX('_calc'!$F$2:$F$3001,$N12)) -> 225450 | I12: =IF($N12="","",INDEX('_calc'!$H$2:$H$3001,$N12)) -> 1504.4232 | J12: =IF($N12="","",INDEX('_calc'!$I$2:$I$3001,$N12)) -> 1471.4726 | K12: =IF($N12="","",IF(OR(I12="",J12=""),"",J12-I12)) -> -32.950595 | L12: =IF($N12="","",INDEX('_calc'!$J$2:$J$3001,$N12)) -> -0.021902477 | M12: =IF($N12="","",IF(AND(G12=0,H12=0),"수량 없음",IF(G12=0,"신규 (전년 수량 없음)",IF(H12=0,"당해 수량 없음","")))) | N12: =IF($B12="","",MATCH($B12,'_calc'!$L$2:$L$3001,0)) -> 18
B13: =IF(ROW()-ROW($B$8)>nComp,"",ROW()-ROW($B$8)) -> 5 | C13: =IF($N13="","",INDEX('_calc'!$A$2:$A$3001,$N13)) -> 파란하이텍 | D13: =IF($N13="","",INDEX('_calc'!$C$2:$C$3001,$N13)) -> 222484560 | E13: =IF($N13="","",INDEX('_calc'!$D$2:$D$3001,$N13)) -> 294634344 | F13: =IF($N13="","",IF($E$8=0,"",E13/$E$8)) -> 0.063934683 | G13: =IF($N13="","",INDEX('_calc'!$E$2:$E$3001,$N13)) -> 56725 | H13: =IF($N13="","",INDEX('_calc'!$F$2:$F$3001,$N13)) -> 76275 | I13: =IF($N13="","",INDEX('_calc'!$H$2:$H$3001,$N13)) -> 3922.1606 | J13: =IF($N13="","",INDEX('_calc'!$I$2:$I$3001,$N13)) -> 3862.7905 | K13: =IF($N13="","",IF(OR(I13="",J13=""),"",J13-I13)) -> -59.370118 | L13: =IF($N13="","",INDEX('_calc'!$J$2:$J$3001,$N13)) -> -0.015137095 | M13: =IF($N13="","",IF(AND(G13=0,H13=0),"수량 없음",IF(G13=0,"신규 (전년 수량 없음)",IF(H13=0,"당해 수량 없음","")))) | N13: =IF($B13="","",MATCH($B13,'_calc'!$L$2:$L$3001,0)) -> 16
B14: =IF(ROW()-ROW($B$8)>nComp,"",ROW()-ROW($B$8)) -> 6 | C14: =IF($N14="","",INDEX('_calc'!$A$2:$A$3001,$N14)) -> 라온테크(주) | D14: =IF($N14="","",INDEX('_calc'!$C$2:$C$3001,$N14)) -> 238900061 | E14: =IF($N14="","",INDEX('_calc'!$D$2:$D$3001,$N14)) -> 284758055 | F14: =IF($N14="","",IF($E$8=0,"",E14/$E$8)) -> 0.061791561 | G14: =IF($N14="","",INDEX('_calc'!$E$2:$E$3001,$N14)) -> 89625 | H14: =IF($N14="","",INDEX('_calc'!$F$2:$F$3001,$N14)) -> 109325 | I14: =IF($N14="","",INDEX('_calc'!$H$2:$H$3001,$N14)) -> 2665.5516 | J14: =IF($N14="","",INDEX('_calc'!$I$2:$I$3001,$N14)) -> 2604.6929 | K14: =IF($N14="","",IF(OR(I14="",J14=""),"",J14-I14)) -> -60.858653 | L14: =IF($N14="","",INDEX('_calc'!$J$2:$J$3001,$N14)) -> -0.022831542 | M14: =IF($N14="","",IF(AND(G14=0,H14=0),"수량 없음",IF(G14=0,"신규 (전년 수량 없음)",IF(H14=0,"당해 수량 없음","")))) | N14: =IF($B14="","",MATCH($B14,'_calc'!$L$2:$L$3001,0)) -> 17
B15: =IF(ROW()-ROW($B$8)>nComp,"",ROW()-ROW($B$8)) -> 7 | C15: =IF($N15="","",INDEX('_calc'!$A$2:$A$3001,$N15)) -> 다솜케미칼 | D15: =IF($N15="","",INDEX('_calc'!$C$2:$C$3001,$N15)) -> 235928564 | E15: =IF($N15="","",INDEX('_calc'!$D$2:$D$3001,$N15)) -> 273632570 | F15: =IF($N15="","",IF($E$8=0,"",E15/$E$8)) -> 0.059377367 | G15: =IF($N15="","",INDEX('_calc'!$E$2:$E$3001,$N15)) -> 69100 | H15: =IF($N15="","",INDEX('_calc'!$F$2:$F$3001,$N15)) -> 76025 | I15: =IF($N15="","",INDEX('_calc'!$H$2:$H$3001,$N15)) -> 3414.3063 | J15: =IF($N15="","",INDEX('_calc'!$I$2:$I$3001,$N15)) -> 3599.2446 | K15: =IF($N15="","",IF(OR(I15="",J15=""),"",J15-I15)) -> 184.93831 | L15: =IF($N15="","",INDEX('_calc'!$J$2:$J$3001,$N15)) -> 0.054165706 | M15: =IF($N15="","",IF(AND(G15=0,H15=0),"수량 없음",IF(G15=0,"신규 (전년 수량 없음)",IF(H15=0,"당해 수량 없음","")))) | N15: =IF($B15="","",MATCH($B15,'_calc'!$L$2:$L$3001,0)) -> 13
B16: =IF(ROW()-ROW($B$8)>nComp,"",ROW()-ROW($B$8)) -> 8 | C16: =IF($N16="","",INDEX('_calc'!$A$2:$A$3001,$N16)) -> 아름화학(주) | D16: =IF($N16="","",INDEX('_calc'!$C$2:$C$3001,$N16)) -> 296920992 | E16: =IF($N16="","",INDEX('_calc'!$D$2:$D$3001,$N16)) -> 270865712 | F16: =IF($N16="","",IF($E$8=0,"",E16/$E$8)) -> 0.058776968 | G16: =IF($N16="","",INDEX('_calc'!$E$2:$E$3001,$N16)) -> 189100 | H16: =IF($N16="","",INDEX('_calc'!$F$2:$F$3001,$N16)) -> 173250 | I16: =IF($N16="","",INDEX('_calc'!$H$2:$H$3001,$N16)) -> 1570.1798 | J16: =IF($N16="","",INDEX('_calc'!$I$2:$I$3001,$N16)) -> 1563.4385 | K16: =IF($N16="","",IF(OR(I16="",J16=""),"",J16-I16)) -> -6.7413036 | L16: =IF($N16="","",INDEX('_calc'!$J$2:$J$3001,$N16)) -> -0.0042933324 | M16: =IF($N16="","",IF(AND(G16=0,H16=0),"수량 없음",IF(G16=0,"신규 (전년 수량 없음)",IF(H16=0,"당해 수량 없음","")))) | N16: =IF($B16="","",MATCH($B16,'_calc'!$L$2:$L$3001,0)) -> 20
B17: =IF(ROW()-ROW($B$8)>nComp,"",ROW()-ROW($B$8)) -> 9 | C17: =IF($N17="","",INDEX('_calc'!$A$2:$A$3001,$N17)) -> 누리오토파츠 | D17: =IF($N17="","",INDEX('_calc'!$C$2:$C$3001,$N17)) -> 209508399 | E17: =IF($N17="","",INDEX('_calc'!$D$2:$D$3001,$N17)) -> 256538685 | F17: =IF($N17="","",IF($E$8=0,"",E17/$E$8)) -> 0.05566805 | G17: =IF($N17="","",INDEX('_calc'!$E$2:$E$3001,$N17)) -> 69975 | H17: =IF($N17="","",INDEX('_calc'!$F$2:$F$3001,$N17)) -> 89625 | I17: =IF($N17="","",INDEX('_calc'!$H$2:$H$3001,$N17)) -> 2994.0464 | J17: =IF($N17="","",INDEX('_calc'!$I$2:$I$3001,$N17)) -> 2862.3563 | K17: =IF($N17="","",IF(OR(I17="",J17=""),"",J17-I17)) -> -131.69011 | L17: =IF($N17="","",INDEX('_calc'!$J$2:$J$3001,$N17)) -> -0.043983992 | M17: =IF($N17="","",IF(AND(G17=0,H17=0),"수량 없음",IF(G17=0,"신규 (전년 수량 없음)",IF(H17=0,"당해 수량 없음","")))) | N17: =IF($B17="","",MATCH($B17,'_calc'!$L$2:$L$3001,0)) -> 9
B18: =IF(ROW()-ROW($B$8)>nComp,"",ROW()-ROW($B$8)) -> 10 | C18: =IF($N18="","",INDEX('_calc'!$A$2:$A$3001,$N18)) -> Hanoi Molding (VN) | D18: =IF($N18="","",INDEX('_calc'!$C$2:$C$3001,$N18)) -> 0 | E18: =IF($N18="","",INDEX('_calc'!$D$2:$D$3001,$N18)) -> 225489827 | F18: =IF($N18="","",IF($E$8=0,"",E18/$E$8)) -> 0.04893055 | G18: =IF($N18="","",INDEX('_calc'!$E$2:$E$3001,$N18)) -> 0 | H18: =IF($N18="","",INDEX('_calc'!$F$2:$F$3001,$N18)) -> 103975 | I18: =IF($N18="","",INDEX('_calc'!$H$2:$H$3001,$N18)) | J18: =IF($N18="","",INDEX('_calc'!$I$2:$I$3001,$N18)) -> 2168.6927 | K18: =IF($N18="","",IF(OR(I18="",J18=""),"",J18-I18)) | L18: =IF($N18="","",INDEX('_calc'!$J$2:$J$3001,$N18)) | M18: =IF($N18="","",IF(AND(G18=0,H18=0),"수량 없음",IF(G18=0,"신규 (전년 수량 없음)",IF(H18=0,"당해 수량 없음","")))) -> 신규 (전년 수량 없음) | N18: =IF($B18="","",MATCH($B18,'_calc'!$L$2:$L$3001,0)) -> 22
B19: =IF(ROW()-ROW($B$8)>nComp,"",ROW()-ROW($B$8)) -> 11 | C19: =IF($N19="","",INDEX('_calc'!$A$2:$A$3001,$N19)) -> 가온소재(주) | D19: =IF($N19="","",INDEX('_calc'!$C$2:$C$3001,$N19)) -> 222809057 | E19: =IF($N19="","",INDEX('_calc'!$D$2:$D$3001,$N19)) -> 225374639 | F19: =IF($N19="","",IF($E$8=0,"",E19/$E$8)) -> 0.048905555 | G19: =IF($N19="","",INDEX('_calc'!$E$2:$E$3001,$N19)) -> 136075 | H19: =IF($N19="","",INDEX('_calc'!$F$2:$F$3001,$N19)) -> 133525 | I19: =IF($N19="","",INDEX('_calc'!$H$2:$H$3001,$N19)) -> 1637.3989 | J19: =IF($N19="","",INDEX('_calc'!$I$2:$I$3001,$N19)) -> 1687.8835 | K19: =IF($N19="","",IF(OR(I19="",J19=""),"",J19-I19)) -> 50.484548 | L19: =IF($N19="","",INDEX('_calc'!$J$2:$J$3001,$N19)) -> 0.030832161 | M19: =IF($N19="","",IF(AND(G19=0,H19=0),"수량 없음",IF(G19=0,"신규 (전년 수량 없음)",IF(H19=0,"당해 수량 없음","")))) | N19: =IF($B19="","",MATCH($B19,'_calc'!$L$2:$L$3001,0)) -> 5
B20: =IF(ROW()-ROW($B$8)>nComp,"",ROW()-ROW($B$8)) -> 12 | C20: =IF($N20="","",INDEX('_calc'!$A$2:$A$3001,$N20)) -> 한울몰드 | D20: =IF($N20="","",INDEX('_calc'!$C$2:$C$3001,$N20)) -> 149086313 | E20: =IF($N20="","",INDEX('_calc'!$D$2:$D$3001,$N20)) -> 189912249 | F20: =IF($N20="","",IF($E$8=0,"",E20/$E$8)) -> 0.041210333 | G20: =IF($N20="","",INDEX('_calc'!$E$2:$E$3001,$N20)) -> 66500 | H20: =IF($N20="","",INDEX('_calc'!$F$2:$F$3001,$N20)) -> 80775 | I20: =IF($N20="","",INDEX('_calc'!$H$2:$H$3001,$N20)) -> 2241.8994 | J20: =IF($N20="","",INDEX('_calc'!$I$2:$I$3001,$N20)) -> 2351.1266 | K20: =IF($N20="","",IF(OR(I20="",J20=""),"",J20-I20)) -> 109.22713 | L20: =IF($N20="","",INDEX('_calc'!$J$2:$J$3001,$N20)) -> 0.048720798 | M20: =IF($N20="","",IF(AND(G20=0,H20=0),"수량 없음",IF(G20=0,"신규 (전년 수량 없음)",IF(H20=0,"당해 수량 없음","")))) | N20: =IF($B20="","",MATCH($B20,'_calc'!$L$2:$L$3001,0)) -> 8
... B3008: =IF(ROW()-ROW($B$8)>nComp,"",ROW()-ROW($B$8)) | C3008: =IF($N3008="","",INDEX('_calc'!$A$2:$A$3001,$N3008)) | D3008: =IF($N3008="","",INDEX('_calc'!$C$2:$C$3001,$N3008)) | E3008: =IF($N3008="","",INDEX('_calc'!$D$2:$D$3001,$N3008)) | F3008: =IF($N3008="","",IF($E$8=0,"",E3008/$E$8)) | G3008: =IF($N3008="","",INDEX('_calc'!$E$2:$E$3001,$N3008)) | H3008: =IF($N3008="","",INDEX('_calc'!$F$2:$F$3001,$N3008)) | I3008: =IF($N3008="","",INDEX('_calc'!$H$2:$H$3001,$N3008)) | J3008: =IF($N3008="","",INDEX('_calc'!$I$2:$I$3001,$N3008)) | K3008: =IF($N3008="","",IF(OR(I3008="",J3008=""),"",J3008-I3008)) | L3008: =IF($N3008="","",INDEX('_calc'!$J$2:$J$3001,$N3008)) | M3008: =IF($N3008="","",IF(AND(G3008=0,H3008=0),"수량 없음",IF(G3008=0,"신규 (전년 수량 없음)",IF(H3008=0,"당해 수량 없음","")))) | N3008: =IF($B3008="","",MATCH($B3008,'_calc'!$L$2:$L$3001,0))

Sheet 설정
B1: 설정 | H1: 내부 계산용
B2: 노란 칸만 입력 / 선택하세요. 나머지는 자동으로 계산됩니다.
B4: ① RAW 데이터 구조
B5: 헤더 행 번호 | C5: 1 | E5: =IF(COUNTA(hdrRow)=0,"✖ 헤더 행이 비어 있음","✔ 헤더 "&COUNTA(hdrRow)&"개") -> ✔ 헤더 19개 | F5: RAW 시트에서 열 이름(헤더)이 있는 행 번호. 보통 1 (리포트 제목 줄이 위에 있으면 그 아래 행 번호) | H5: =IFERROR(MIN(MAX(1,INT(C5)),1000),1) -> 1
B7: ② 열 매핑 — RAW 헤더명 선택
B8: 항목 | C8: RAW 헤더명 (드롭다운) | D8: 찾은 위치 | E8: 상태 | F8: 설명
B9: 기간 | C9: 청구일 | D9: =IF($H9=16384,"",SUBSTITUTE(ADDRESS(1,$H9,4),"1","")&" 열") -> I 열 | E9: =IF($C9="","✖ 미선택",IF($H9=16384,"✖ 헤더 없음",IF(COUNTIF(hdrRow,$C9)>1,"⚠ 같은 헤더 여러 개(첫 열 사용)","✔ 정상"))) -> ✔ 정상 | F9: 기간 판정에 쓰는 열: 날짜 / 연도(2026) / 연월(202609) 형식의 숫자 | H9: =IF($C9="",16384,IFERROR(MATCH($C9,hdrRow,0),16384)) -> 9
B10: 업체 | C10: 고객명 | D10: =IF($H10=16384,"",SUBSTITUTE(ADDRESS(1,$H10,4),"1","")&" 열") -> E 열 | E10: =IF($C10="","✖ 미선택",IF($H10=16384,"✖ 헤더 없음",IF(COUNTIF(hdrRow,$C10)>1,"⚠ 같은 헤더 여러 개(첫 열 사용)","✔ 정상"))) -> ✔ 정상 | F10: 업체별로 묶는 기준 열 (고객명, 고객코드 등) | H10: =IF($C10="",16384,IFERROR(MATCH($C10,hdrRow,0),16384)) -> 5
B11: 수량 | C11: 판매수량 | D11: =IF($H11=16384,"",SUBSTITUTE(ADDRESS(1,$H11,4),"1","")&" 열") -> K 열 | E11: =IF($C11="","✖ 미선택",IF($H11=16384,"✖ 헤더 없음",IF(COUNTIF(hdrRow,$C11)>1,"⚠ 같은 헤더 여러 개(첫 열 사용)","✔ 정상"))) -> ✔ 정상 | F11: ASP의 분모 (판매수량) | H11: =IF($C11="",16384,IFERROR(MATCH($C11,hdrRow,0),16384)) -> 11
B12: 매출액 | C12: 순매출액 | D12: =IF($H12=16384,"",SUBSTITUTE(ADDRESS(1,$H12,4),"1","")&" 열") -> P 열 | E12: =IF($C12="","✖ 미선택",IF($H12=16384,"✖ 헤더 없음",IF(COUNTIF(hdrRow,$C12)>1,"⚠ 같은 헤더 여러 개(첫 열 사용)","✔ 정상"))) -> ✔ 정상 | F12: ASP의 분자 — Realized price 기준 금액 (예: 할인·리베이트 차감 후 순매출액) | H12: =IF($C12="",16384,IFERROR(MATCH($C12,hdrRow,0),16384)) -> 16
B14: ③ 비교 기간
B15: 구분 | C15: 시작 | D15: 종료 | E15: 표시 | F15: 설명
B16: 당해 (CY) | C16: 46023 | D16: 46295 | E16: =IF(OR(NOT(ISNUMBER(C16)),NOT(ISNUMBER(D16))),"",IF(AND(C16>=3000,C16<100000),TEXT(C16,"yyyy.mm.dd"),TEXT(C16,"0"))&IF(C16=D16,""," ~ "&IF(AND(D16>=3000,D16<100000),TEXT(D16,"yyyy.mm.dd"),TEXT(D16,"0")))) -> 2026.01.01 ~ 2026.09.30 | F16: 기간 열과 같은 형식으로 입력: 날짜 2026-01-01 / 연도 2026 / 연월 202601
B17: 전년 직접 지정 (선택) | F17: 비워 두면 당해의 1년 전 기간이 자동으로 적용됩니다. 다른 기간과 비교할 때만 입력
B18: 전년 (PY) 적용 | C18: =IF(C17<>"",C17,IF(NOT(ISNUMBER(C16)),"",IF(C16<3000,C16-1,IF(C16<100000,EDATE(C16,-12),IF(C16<1000000,C16-100,C16-10000))))) -> 45658 | D18: =IF(D17<>"",D17,IF(NOT(ISNUMBER(D16)),"",IF(D16<3000,D16-1,IF(D16<100000,EDATE(D16,-12),IF(D16<1000000,D16-100,D16-10000))))) -> 45930 | E18: =IF(OR(NOT(ISNUMBER(C18)),NOT(ISNUMBER(D18))),"",IF(AND(C18>=3000,C18<100000),TEXT(C18,"yyyy.mm.dd"),TEXT(C18,"0"))&IF(C18=D18,""," ~ "&IF(AND(D18>=3000,D18<100000),TEXT(D18,"yyyy.mm.dd"),TEXT(D18,"0")))) -> 2025.01.01 ~ 2025.09.30 | F18: 실제 비교에 쓰이는 전년 기간 (자동 계산)
B20: ④ 필터 (선택 — 비우면 전체 데이터)
B21: 구분 | C21: RAW 헤더명 (드롭다운) | D21: 조건 값 | E21: 상태 | F21: 설명
B22: 필터 1 | C22: 사업부 | E22: =IF(AND($C22="",$D22=""),"– 미사용",IF($D22="","– 미적용 (조건 값 없음)",IF($C22="","⚠ 헤더 미선택",IF(ISNA(MATCH($C22,hdrRow,0)),"✖ 헤더 없음","✔ 적용")))) -> – 미적용 (조건 값 없음) | F22: 예) 사업부 = 범용수지사업부 / 조건 값에 <>내부거래 처럼 쓰면 '제외' | H22: =IF(OR($C22="",$D22=""),16384,IFERROR(MATCH($C22,hdrRow,0),16384)) -> 16384 | I22: =IF($H22=16384,"<>§NOFILTER§",$D22) -> <>§NOFILTER§
B23: 필터 2 | C23: 제품군 | E23: =IF(AND($C23="",$D23=""),"– 미사용",IF($D23="","– 미적용 (조건 값 없음)",IF($C23="","⚠ 헤더 미선택",IF(ISNA(MATCH($C23,hdrRow,0)),"✖ 헤더 없음","✔ 적용")))) -> – 미적용 (조건 값 없음) | F23: 예) 제품군 = PP / PP* 처럼 * 를 쓰면 'PP로 시작하는 값' | H23: =IF(OR($C23="",$D23=""),16384,IFERROR(MATCH($C23,hdrRow,0),16384)) -> 16384 | I23: =IF($H23=16384,"<>§NOFILTER§",$D23) -> <>§NOFILTER§
B24: 필터 3 | C24: 통화 | E24: =IF(AND($C24="",$D24=""),"– 미사용",IF($D24="","– 미적용 (조건 값 없음)",IF($C24="","⚠ 헤더 미선택",IF(ISNA(MATCH($C24,hdrRow,0)),"✖ 헤더 없음","✔ 적용")))) -> – 미적용 (조건 값 없음) | F24: 예) 통화 = KRW 또는 단위 = KG (단위·통화가 섞여 있으면 꼭 지정) | H24: =IF(OR($C24="",$D24=""),16384,IFERROR(MATCH($C24,hdrRow,0),16384)) -> 16384 | I24: =IF($H24=16384,"<>§NOFILTER§",$D24) -> <>§NOFILTER§
B25: 적용 중인 필터 | C25: =IF(COUNTIF($E$22:$E$24,"✔*")=0,"없음 (전체 데이터)",LEFT(IF(LEFT($E22,1)="✔",$C22&IF(LEFT($D22,2)="<>"," ≠ "&MID($D22,3,999)," = "&$D22)&" · ","")&IF(LEFT($E23,1)="✔",$C23&IF(LEFT($D23,2)="<>"," ≠ "&MID($D23,3,999)," = "&$D23)&" · ","")&IF(LEFT($E24,1)="✔",$C24&IF(LEFT($D24,2)="<>"," ≠ "&MID($D24,3,999)," = "&$D24)&" · ",""),LEN(IF(LEFT($E22,1)="✔",$C22&IF(LEFT($D22,2)="<>"," ≠ "&MID($D22,3,999)," = "&$D22)&" · ","")&IF(LEFT($E23,1)="✔",$C23&IF(LEFT($D23,2)="<>"," ≠ "&MID($D23,3,999)," = "&$D23)&" · ","")&IF(LEFT($E24,1)="✔",$C24&IF(LEFT($D24,2)="<>"," ≠ "&MID($D24,3,999)," = "&$D24)&" · ",""))-5)) -> 없음 (전체 데이터)
B27: ⑤ 표시 옵션
B28: 업체 정렬 기준 | C28: 당해 매출액 큰 순 | F28: 업체별 ASP 표의 정렬 순서 (드롭다운) | H28: =IFERROR(MATCH(C28,sortList,0),1) -> 1
B30: ⑥ 데이터 점검
B31: 점검 항목 | C31: 결과 | E31: 상태 | F31: 확인 / 조치 방법
B32: RAW 데이터 행 수 | C32: =MAX(COUNTA(dPer),COUNTA(dCust),COUNTA(dQty),COUNTA(dAmt)) -> 1025 | E32: =IF(C32>0,"✔ 정상","✖ 데이터 없음") -> ✔ 정상 | F32: RAW 시트의 헤더 행(보통 1행)부터 데이터를 헤더 포함 붙여넣으세요.
B33: 필수 열 찾기 | C33: =COUNTIF($E$9:$E$12,"✔*")+COUNTIF($E$9:$E$12,"⚠*")&" / 4 열" -> 4 / 4 열 | E33: =IF(COUNTIF($E$9:$E$12,"✖*")>0,"✖ 확인 필요",IF(COUNTIF($E$9:$E$12,"⚠*")>0,"⚠ 중복 헤더","✔ 정상")) -> ✔ 정상 | F33: ② 열 매핑에서 RAW 헤더명을 드롭다운으로 다시 선택하세요.
B34: 비교 기간 입력 | C34: =IF(AND(ISNUMBER(C16),ISNUMBER(D16),ISNUMBER(C18),ISNUMBER(D18)),"입력됨","입력 필요") -> 입력됨 | E34: =IF(AND(ISNUMBER(C16),ISNUMBER(D16),ISNUMBER(C18),ISNUMBER(D18)),IF(AND(C16<=D16,C18<=D18),"✔ 정상","✖ 시작 > 종료"),"✖ 확인 필요") -> ✔ 정상 | F34: ③ 비교 기간을 날짜(2026-01-01) / 연도(2026) / 연월(202601) 숫자로 입력하세요.
B35: 기간 열 형식 | C35: ="날짜·숫자 "&TEXT(COUNT(dPer),"#,##0")&"행 / 텍스트 "&TEXT(SUMPRODUCT(--ISTEXT(dPer)),"#,##0")&"행" -> 날짜·숫자 1,025행 / 텍스트 0행 | E35: =IF(COUNTA(dPer)=0,"✖ 데이터 없음",IF(SUMPRODUCT(--ISTEXT(dPer))>0,"⚠ 텍스트 포함","✔ 정상")) -> ✔ 정상 | F35: 텍스트로 된 날짜는 기간 판정에서 빠집니다 → RAW에서 그 열 선택 > 데이터 > 텍스트 나누기 > 마침
B36: 수량·매출액 숫자 형식 | C36: ="텍스트 "&TEXT(SUMPRODUCT(--ISTEXT(dQty))+SUMPRODUCT(--ISTEXT(dAmt)),"#,##0")&"셀" -> 텍스트 0셀 | E36: =IF(SUMPRODUCT(--ISTEXT(dQty))+SUMPRODUCT(--ISTEXT(dAmt))>0,"⚠ 텍스트 포함","✔ 정상") -> ✔ 정상 | F36: 숫자가 텍스트로 저장된 셀은 합계에서 빠집니다 → 그 열 선택 > 데이터 > 텍스트 나누기 > 마침
B37: 오류 값 셀 | C37: =SUMPRODUCT(--ISERROR(dPer))+SUMPRODUCT(--ISERROR(dCust))+SUMPRODUCT(--ISERROR(dQty))+SUMPRODUCT(--ISERROR(dAmt)) -> 0 | E37: =IF(C37>0,"⚠ 오류 셀 있음","✔ 정상") -> ✔ 정상 | F37: 오류 값(N/A, VALUE! 등) 셀은 합계에서 빠집니다 → RAW에서 홈 > 찾기 및 선택 > 이동 옵션 > 상수 > 오류만 체크 → 확인 → Delete
B38: 당해 기간 데이터 | C38: =COUNTIFS(dPer,">="&cyFrom,dPer,"<="&cyTo,dFlt1,critFlt1,dFlt2,critFlt2,dFlt3,critFlt3) -> 460 | E38: =IF(C38>0,"✔ 정상","✖ 해당 행 없음") -> ✔ 정상 | F38: 당해 기간·필터에 맞는 행이 없습니다 → ③ 기간 형식과 값, ④ 필터를 확인하세요.
B39: 전년 기간 데이터 | C39: =COUNTIFS(dPer,">="&pyFrom,dPer,"<="&pyTo,dFlt1,critFlt1,dFlt2,critFlt2,dFlt3,critFlt3) -> 418 | E39: =IF(C39>0,"✔ 정상","✖ 해당 행 없음") -> ✔ 정상 | F39: 전년 기간·필터에 맞는 행이 없습니다 → 전년 데이터가 RAW에 함께 들어 있는지 확인하세요.
B40: 필터 | C40: =COUNTIF($E$22:$E$24,"✔*")&"개 적용" -> 0개 적용 | E40: =IF(COUNTIF($E$22:$E$24,"✖*")+COUNTIF($E$22:$E$24,"⚠*")>0,"⚠ 확인 필요","✔ 정상") -> ✔ 정상 | F40: ④ 필터의 헤더명이 RAW에 있는지 확인하세요.
B41: 업체 목록 생성 | C41: =IF(ISERROR('_calc'!$A$2),"목록 오류",IF(dynNA,"직접 입력 ","자동 생성 ")&TEXT(nList,"#,##0")&"개") -> 자동 생성 22개 | E41: =IF(ISERROR('_calc'!$A$2),"✖ _calc 시트 A열 확인",IF(dynNA,IF(nList=0,"✖ Excel 2021 이상 필요","✔ 직접 입력 목록"),"✔ 정상")) -> ✔ 정상 | F41: Excel 2019 이하는 자동 생성이 안 됩니다 → _calc 시트 숨기기 취소 → A2부터 업체 목록 붙여넣기 (RAW의 업체 열 복사 → 데이터 > 중복된 항목 제거)
B42: 업체 수 | C42: =TEXT(nComp,"#,##0")&"개 표시 / 한도 3,000" -> 22개 표시 / 한도 3,000 | E42: =IF(nList>3000,"⚠ 한도 초과","✔ 정상") -> ✔ 정상 | F42: 업체가 3,000개를 넘으면 나머지는 표시되지 않습니다 → ④ 필터로 나눠서 보세요.
B43: 합계 검증 (업체 합 = 전체) | C43: ="매출 차이 "&TEXT(H43,"#,##0")&" / 수량 차이 "&TEXT(I43,"#,##0") -> 매출 차이 0 / 수량 차이 0 | E43: =IF(AND(ROUND(H43,0)=0,ROUND(I43,0)=0),"✔ 일치","⚠ 불일치") -> ✔ 일치 | F43: ="업체명이 빈 행의 매출액(당해+전년): "&TEXT(SUMIFS(dAmt,dCust,"",dPer,">="&cyFrom,dPer,"<="&cyTo,dAmt,">-1E+300",dFlt1,critFlt1,dFlt2,critFlt2,dFlt3,critFlt3)+SUMIFS(dAmt,dCust,"",dPer,">="&pyFrom,dPer,"<="&pyTo,dAmt,">-1E+300",dFlt1,critFlt1,dFlt2,critFlt2,dFlt3,critFlt3),"#,##0")&" → 업체 열이 빈 행은 업체별 표에서 빠집니다" -> 업체명이 빈 행의 매출액(당해+전년): 0 → 업체 열이 빈 행은 업체별 표에서 빠집니다 | H43: =ABS(SUM('_calc'!$C$2:$C$3001)-'업체별 ASP'!$D$8)+ABS(SUM('_calc'!$D$2:$D$3001)-'업체별 ASP'!$E$8) -> 0 | I43: =ABS(SUM('_calc'!$E$2:$E$3001)-'업체별 ASP'!$G$8)+ABS(SUM('_calc'!$F$2:$F$3001)-'업체별 ASP'!$H$8) -> 0
B44: 예시 데이터 | C44: =IF(COUNTIF(RAW!$S:$S,"※예시데이터")>0,"예시 데이터 사용 중","없음") -> 예시 데이터 사용 중 | E44: =IF(COUNTIF(RAW!$S:$S,"※예시데이터")>0,"⚠ 예시 데이터","✔ 정상") -> ⚠ 예시 데이터 | F44: 실제 데이터를 붙여넣기 전에 RAW 시트 전체를 지우세요 (Ctrl+A → Delete).
B45: 종합 | C45: =COUNTIF($E$32:$E$44,"✖*")+COUNTIF($E$32:$E$44,"⚠*") -> 1 | E45: =IF(C45=0,"✔ 이상 없음","⚠ "&C45&"건 확인 필요") -> ⚠ 1건 확인 필요

Sheet RAW
A1: 회사코드 | B1: 사업부 | C1: 판매조직 | D1: 고객코드 | E1: 고객명 | F1: 제품군 | G1: 제품코드 | H1: 제품명 | I1: 청구일 | J1: 청구연월 | K1: 판매수량 | L1: 단위 | M1: 총매출액 | N1: 할인액 | O1: 리베이트 | P1: 순매출액 | Q1: 통화 | R1: 전표번호 | S1: ※예시데이터
A2: 1000 | B2: EP사업부 | C2: 국내영업1팀 | D2: C10057 | E2: 자연엠텍 | F2: PC | G2: M-2201 | H2: PC 일반 C100 | I2: 45658 | J2: 202501 | K2: 2500 | L2: KG | M2: 9799226 | N2: 489961 | O2: 0 | P2: 9309265 | Q2: KRW | R2: INV2501-00001 | S2: ※예시데이터
A3: 1000 | B3: EP사업부 | C3: 국내영업1팀 | D3: C10043 | E3: 새봄플라스틱 | F3: ABS | G3: M-2102 | H3: ABS 내열 HR500 | I3: 45659 | J3: 202501 | K3: 2075 | L3: KG | M3: 6214719 | N3: 372883 | O3: 0 | P3: 5841836 | Q3: KRW | R3: INV2501-00002 | S3: ※예시데이터
A4: 1000 | B4: 범용수지사업부 | C4: 국내영업1팀 | D4: C10106 | E4: 온새미사출 | F4: PP | G4: M-1101 | H4: PP 범용사출 H110 | I4: 45660 | J4: 202501 | K4: 4625 | L4: KG | M4: 7669779 | N4: 383489 | O4: 0 | P4: 7286290 | Q4: KRW | R4: INV2501-00003 | S4: ※예시데이터
A5: 1000 | B5: EP사업부 | C5: 국내영업1팀 | D5: C10134 | E5: 별하전자(주) | F5: PC | G5: M-2201 | H5: PC 일반 C100 | I5: 45660 | J5: 202501 | K5: 750 | L5: KG | M5: 2939768 | N5: 88193 | O5: 0 | P5: 2851575 | Q5: KRW | R5: INV2501-00004 | S5: ※예시데이터
A6: 1000 | B6: 범용수지사업부 | C6: 국내영업1팀 | D6: C10001 | E6: 가온소재(주) | F6: PP | G6: M-1102 | H6: PP 고강성 H220 | I6: 45661 | J6: 202501 | K6: 1925 | L6: KG | M6: 3521189 | N6: 211271 | O6: 0 | P6: 3309918 | Q6: KRW | R6: INV2501-00005 | S6: ※예시데이터
A7: 1000 | B7: 범용수지사업부 | C7: 해외영업팀 | D7: C10071 | E7: 큰별코리아 | F7: PE | G7: M-1202 | H7: LLDPE 필름 F120 | I7: 45663 | J7: 202501 | K7: 7475 | L7: KG | M7: 12846785 | N7: 1413146 | O7: 256936 | P7: 11176703 | Q7: KRW | R7: INV2501-00006 | S7: ※예시데이터
A8: 1000 | B8: 범용수지사업부 | C8: 국내영업1팀 | D8: C10092 | E8: 하늘포장(주) | F8: PE | G8: M-1201 | H8: HDPE 블로우 B500 | I8: 45663 | J8: 202501 | K8: 13775 | L8: KG | M8: 21874385 | N8: 1749951 | O8: 0 | P8: 20124434 | Q8: KRW | R8: INV2501-00007 | S8: ※예시데이터
A9: 1000 | B9: 범용수지사업부 | C9: 국내영업2팀 | D9: C10099 | E9: 한울몰드 | F9: PP | G9: M-1101 | H9: PP 범용사출 H110 | I9: 45663 | J9: 202501 | K9: 1950 | L9: KG | M9: 3233745 | N9: 194025 | O9: 0 | P9: 3039720 | Q9: KRW | R9: INV2501-00008 | S9: ※예시데이터
A10: 1000 | B10: EP사업부 | C10: 국내영업2팀 | D10: C10113 | E10: 누리오토파츠 | F10: PC | G10: M-2202 | H10: PC 난연 FR200 | I10: 45663 | J10: 202501 | K10: 2800 | L10: KG | M10: 12241495 | N10: 856905 | O10: 122415 | P10: 11262175 | Q10: KRW | R10: INV2501-00009 | S10: ※예시데이터
A11: 1000 | B11: 범용수지사업부 | C11: 국내영업2팀 | D11: C10127 | E11: 미르패키징 | F11: PP | G11: M-1101 | H11: PP 범용사출 H110 | I11: 45663 | J11: 202501 | K11: 4300 | L11: KG | M11: 7130821 | N11: 641774 | O11: 0 | P11: 6489047 | Q11: KRW | R11: INV2501-00010 | S11: ※예시데이터
A12: 1000 | B12: 범용수지사업부 | C12: 국내영업2팀 | D12: C10127 | E12: 미르패키징 | F12: PE | G12: M-1202 | H12: LLDPE 필름 F120 | I12: 45663 | J12: 202501 | K12: 3775 | L12: KG | M12: 6487841 | N12: 583906 | O12: 0 | P12: 5903935 | Q12: KRW | R12: INV2501-00011 | S12: ※예시데이터
A13: 1000 | B13: 범용수지사업부 | C13: 국내영업1팀 | D13: C10001 | E13: 가온소재(주) | F13: PP | G13: M-1102 | H13: PP 고강성 H220 | I13: 45664 | J13: 202501 | K13: 1925 | L13: KG | M13: 3521189 | N13: 211271 | O13: 0 | P13: 3309918 | Q13: KRW | R13: INV2501-00012 | S13: ※예시데이터
... A1026: 1000 | B1026: 범용수지사업부 | C1026: 국내영업2팀 | D1026: C10127 | E1026: 미르패키징 | F1026: PE | G1026: M-1202 | H1026: LLDPE 필름 F120 | I1026: 46293 | J1026: 202609 | K1026: 4075 | L1026: KG | M1026: 6880698 | N1026: 584859 | O1026: 0 | P1026: 6295839 | Q1026: KRW | R1026: INV2609-01025 | S1026: ※예시데이터

Sheet _calc
A1: 업체 | B1: SUMIFS 조건 | C1: 매출 전년 | D1: 매출 당해 | E1: 수량 전년 | F1: 수량 당해 | G1: 활성 | H1: ASP 전년 | I1: ASP 당해 | J1: ASP 증감률 | K1: 정렬 키 | L1: 순위
A2: {=IFERROR(_xlfn.UNIQUE(_xlfn._xlws.FILTER(dCust,IFERROR((dCust<>"")*((dPer>=cyFrom)*(dPer<=cyTo)+(dPer>=pyFrom)*(dPer<=pyTo)),0))),"")} -> 자연엠텍 | B2: =IFERROR(IF(A2="","","="&SUBSTITUTE(SUBSTITUTE(SUBSTITUTE(A2,"~","~~"),"*","~*"),"?","~?")),"") -> =자연엠텍 | C2: =IF($B2="","",SUMIFS(dAmt,dCust,$B2,dPer,">="&pyFrom,dPer,"<="&pyTo,dAmt,">-1E+300",dFlt1,critFlt1,dFlt2,critFlt2,dFlt3,critFlt3)) -> 170559813 | D2: =IF($B2="","",SUMIFS(dAmt,dCust,$B2,dPer,">="&cyFrom,dPer,"<="&cyTo,dAmt,">-1E+300",dFlt1,critFlt1,dFlt2,critFlt2,dFlt3,critFlt3)) -> 121073379 | E2: =IF($B2="","",SUMIFS(dQty,dCust,$B2,dPer,">="&pyFrom,dPer,"<="&pyTo,dQty,">-1E+300",dFlt1,critFlt1,dFlt2,critFlt2,dFlt3,critFlt3)) -> 53775 | F2: =IF($B2="","",SUMIFS(dQty,dCust,$B2,dPer,">="&cyFrom,dPer,"<="&cyTo,dQty,">-1E+300",dFlt1,critFlt1,dFlt2,critFlt2,dFlt3,critFlt3)) -> 37750 | G2: =IF($B2="",0,IFERROR(IF(OR(C2<>0,D2<>0,E2<>0,F2<>0),1,0),1)) -> 1 | H2: =IF(OR(G2=0,E2=0),"",C2/E2) -> 3171.7306 | I2: =IF(OR(G2=0,F2=0),"",D2/F2) -> 3207.2418 | J2: =IF(OR(H2="",I2=""),"",IF(H2=0,"",I2/H2-1)) -> 0.011196168 | K2: =IF($B2="","",IFERROR(IF(G2=0,-2E+300,CHOOSE(sortIdx,ROUND(D2,0),IF(J2="",-1E+300,ROUND(-J2,6)),IF(J2="",-1E+300,ROUND(J2,6)))),-1.5E+300)) -> 121073379 | L2: =IF(K2="","",RANK(K2,$K$2:$K$3001,0)+COUNTIF($K$2:K2,K2)-1) -> 16 | P2: 표시 업체 수 | Q2: =IF(mapOK,SUM($G$2:$G$3001),0) -> 22
A3: 새봄플라스틱 | B3: =IFERROR(IF(A3="","","="&SUBSTITUTE(SUBSTITUTE(SUBSTITUTE(A3,"~","~~"),"*","~*"),"?","~?")),"") -> =새봄플라스틱 | C3: =IF($B3="","",SUMIFS(dAmt,dCust,$B3,dPer,">="&pyFrom,dPer,"<="&pyTo,dAmt,">-1E+300",dFlt1,critFlt1,dFlt2,critFlt2,dFlt3,critFlt3)) -> 202915490 | D3: =IF($B3="","",SUMIFS(dAmt,dCust,$B3,dPer,">="&cyFrom,dPer,"<="&cyTo,dAmt,">-1E+300",dFlt1,critFlt1,dFlt2,critFlt2,dFlt3,critFlt3)) -> 350242959 | E3: =IF($B3="","",SUMIFS(dQty,dCust,$B3,dPer,">="&pyFrom,dPer,"<="&pyTo,dQty,">-1E+300",dFlt1,critFlt1,dFlt2,critFlt2,dFlt3,critFlt3)) -> 84650 | F3: =IF($B3="","",SUMIFS(dQty,dCust,$B3,dPer,">="&cyFrom,dPer,"<="&cyTo,dQty,">-1E+300",dFlt1,critFlt1,dFlt2,critFlt2,dFlt3,critFlt3)) -> 136300 | G3: =IF($B3="",0,IFERROR(IF(OR(C3<>0,D3<>0,E3<>0,F3<>0),1,0),1)) -> 1 | H3: =IF(OR(G3=0,E3=0),"",C3/E3) -> 2397.1115 | I3: =IF(OR(G3=0,F3=0),"",D3/F3) -> 2569.6475 | J3: =IF(OR(H3="",I3=""),"",IF(H3=0,"",I3/H3-1)) -> 0.071976633 | K3: =IF($B3="","",IFERROR(IF(G3=0,-2E+300,CHOOSE(sortIdx,ROUND(D3,0),IF(J3="",-1E+300,ROUND(-J3,6)),IF(J3="",-1E+300,ROUND(J3,6)))),-1.5E+300)) -> 350242959 | L3: =IF(K3="","",RANK(K3,$K$2:$K$3001,0)+COUNTIF($K$2:K3,K3)-1) -> 3 | P3: 헤더 마지막 열 | Q3: =IFERROR(LOOKUP(2,1/(hdrRow<>""),COLUMN(hdrRow)),1) -> 19
A4: 온새미사출 | B4: =IFERROR(IF(A4="","","="&SUBSTITUTE(SUBSTITUTE(SUBSTITUTE(A4,"~","~~"),"*","~*"),"?","~?")),"") -> =온새미사출 | C4: =IF($B4="","",SUMIFS(dAmt,dCust,$B4,dPer,">="&pyFrom,dPer,"<="&pyTo,dAmt,">-1E+300",dFlt1,critFlt1,dFlt2,critFlt2,dFlt3,critFlt3)) -> 112494196 | D4: =IF($B4="","",SUMIFS(dAmt,dCust,$B4,dPer,">="&cyFrom,dPer,"<="&cyTo,dAmt,">-1E+300",dFlt1,critFlt1,dFlt2,critFlt2,dFlt3,critFlt3)) -> 86899087 | E4: =IF($B4="","",SUMIFS(dQty,dCust,$B4,dPer,">="&pyFrom,dPer,"<="&pyTo,dQty,">-1E+300",dFlt1,critFlt1,dFlt2,critFlt2,dFlt3,critFlt3)) -> 71725 | F4: =IF($B4="","",SUMIFS(dQty,dCust,$B4,dPer,">="&cyFrom,dPer,"<="&cyTo,dQty,">-1E+300",dFlt1,critFlt1,dFlt2,critFlt2,dFlt3,critFlt3)) -> 53750 | G4: =IF($B4="",0,IFERROR(IF(OR(C4<>0,D4<>0,E4<>0,F4<>0),1,0),1)) -> 1 | H4: =IF(OR(G4=0,E4=0),"",C4/E4) -> 1568.4098 | I4: =IF(OR(G4=0,F4=0),"",D4/F4) -> 1616.7272 | J4: =IF(OR(H4="",I4=""),"",IF(H4=0,"",I4/H4-1)) -> 0.030806589 | K4: =IF($B4="","",IFERROR(IF(G4=0,-2E+300,CHOOSE(sortIdx,ROUND(D4,0),IF(J4="",-1E+300,ROUND(-J4,6)),IF(J4="",-1E+300,ROUND(J4,6)))),-1.5E+300)) -> 86899087 | L4: =IF(K4="","",RANK(K4,$K$2:$K$3001,0)+COUNTIF($K$2:K4,K4)-1) -> 20 | P4: 업체 목록 개수 | Q4: =COUNTA($A$2:$A$1048576)-IFERROR(IF($A$2="",1,0),0) -> 22
A5: 별하전자(주) | B5: =IFERROR(IF(A5="","","="&SUBSTITUTE(SUBSTITUTE(SUBSTITUTE(A5,"~","~~"),"*","~*"),"?","~?")),"") -> =별하전자(주) | C5: =IF($B5="","",SUMIFS(dAmt,dCust,$B5,dPer,">="&pyFrom,dPer,"<="&pyTo,dAmt,">-1E+300",dFlt1,critFlt1,dFlt2,critFlt2,dFlt3,critFlt3)) -> 84466240 | D5: =IF($B5="","",SUMIFS(dAmt,dCust,$B5,dPer,">="&cyFrom,dPer,"<="&cyTo,dAmt,">-1E+300",dFlt1,critFlt1,dFlt2,critFlt2,dFlt3,critFlt3)) -> 87276521 | E5: =IF($B5="","",SUMIFS(dQty,dCust,$B5,dPer,">="&pyFrom,dPer,"<="&pyTo,dQty,">-1E+300",dFlt1,critFlt1,dFlt2,critFlt2,dFlt3,critFlt3)) -> 21150 | F5: =IF($B5="","",SUMIFS(dQty,dCust,$B5,dPer,">="&cyFrom,dPer,"<="&cyTo,dQty,">-1E+300",dFlt1,critFlt1,dFlt2,critFlt2,dFlt3,critFlt3)) -> 21575 | G5: =IF($B5="",0,IFERROR(IF(OR(C5<>0,D5<>0,E5<>0,F5<>0),1,0),1)) -> 1 | H5: =IF(OR(G5=0,E5=0),"",C5/E5) -> 3993.6757 | I5: =IF(OR(G5=0,F5=0),"",D5/F5) -> 4045.2617 | J5: =IF(OR(H5="",I5=""),"",IF(H5=0,"",I5/H5-1)) -> 0.012916933 | K5: =IF($B5="","",IFERROR(IF(G5=0,-2E+300,CHOOSE(sortIdx,ROUND(D5,0),IF(J5="",-1E+300,ROUND(-J5,6)),IF(J5="",-1E+300,ROUND(J5,6)))),-1.5E+300)) -> 87276521 | L5: =IF(K5="","",RANK(K5,$K$2:$K$3001,0)+COUNTIF($K$2:K5,K5)-1) -> 19 | P5: 필수 열 모두 찾음 | Q5: =COUNTIF('설정'!$E$9:$E$12,"✖*")=0 -> TRUE
A6: 가온소재(주) | B6: =IFERROR(IF(A6="","","="&SUBSTITUTE(SUBSTITUTE(SUBSTITUTE(A6,"~","~~"),"*","~*"),"?","~?")),"") -> =가온소재(주) | C6: =IF($B6="","",SUMIFS(dAmt,dCust,$B6,dPer,">="&pyFrom,dPer,"<="&pyTo,dAmt,">-1E+300",dFlt1,critFlt1,dFlt2,critFlt2,dFlt3,critFlt3)) -> 222809057 | D6: =IF($B6="","",SUMIFS(dAmt,dCust,$B6,dPer,">="&cyFrom,dPer,"<="&cyTo,dAmt,">-1E+300",dFlt1,critFlt1,dFlt2,critFlt2,dFlt3,critFlt3)) -> 225374639 | E6: =IF($B6="","",SUMIFS(dQty,dCust,$B6,dPer,">="&pyFrom,dPer,"<="&pyTo,dQty,">-1E+300",dFlt1,critFlt1,dFlt2,critFlt2,dFlt3,critFlt3)) -> 136075 | F6: =IF($B6="","",SUMIFS(dQty,dCust,$B6,dPer,">="&cyFrom,dPer,"<="&cyTo,dQty,">-1E+300",dFlt1,critFlt1,dFlt2,critFlt2,dFlt3,critFlt3)) -> 133525 | G6: =IF($B6="",0,IFERROR(IF(OR(C6<>0,D6<>0,E6<>0,F6<>0),1,0),1)) -> 1 | H6: =IF(OR(G6=0,E6=0),"",C6/E6) -> 1637.3989 | I6: =IF(OR(G6=0,F6=0),"",D6/F6) -> 1687.8835 | J6: =IF(OR(H6="",I6=""),"",IF(H6=0,"",I6/H6-1)) -> 0.030832161 | K6: =IF($B6="","",IFERROR(IF(G6=0,-2E+300,CHOOSE(sortIdx,ROUND(D6,0),IF(J6="",-1E+300,ROUND(-J6,6)),IF(J6="",-1E+300,ROUND(J6,6)))),-1.5E+300)) -> 225374639 | L6: =IF(K6="","",RANK(K6,$K$2:$K$3001,0)+COUNTIF($K$2:K6,K6)-1) -> 11 | P6: 동적 배열 미지원 | Q6: {=ISERROR(_xlfn.UNIQUE({1;1}))} -> FALSE
A7: 큰별코리아 | B7: =IFERROR(IF(A7="","","="&SUBSTITUTE(SUBSTITUTE(SUBSTITUTE(A7,"~","~~"),"*","~*"),"?","~?")),"") -> =큰별코리아 | C7: =IF($B7="","",SUMIFS(dAmt,dCust,$B7,dPer,">="&pyFrom,dPer,"<="&pyTo,dAmt,">-1E+300",dFlt1,critFlt1,dFlt2,critFlt2,dFlt3,critFlt3)) -> 290530624 | D7: =IF($B7="","",SUMIFS(dAmt,dCust,$B7,dPer,">="&cyFrom,dPer,"<="&cyTo,dAmt,">-1E+300",dFlt1,critFlt1,dFlt2,critFlt2,dFlt3,critFlt3)) -> 381024971 | E7: =IF($B7="","",SUMIFS(dQty,dCust,$B7,dPer,">="&pyFrom,dPer,"<="&pyTo,dQty,">-1E+300",dFlt1,critFlt1,dFlt2,critFlt2,dFlt3,critFlt3)) -> 202875 | F7: =IF($B7="","",SUMIFS(dQty,dCust,$B7,dPer,">="&cyFrom,dPer,"<="&cyTo,dQty,">-1E+300",dFlt1,critFlt1,dFlt2,critFlt2,dFlt3,critFlt3)) -> 270000 | G7: =IF($B7="",0,IFERROR(IF(OR(C7<>0,D7<>0,E7<>0,F7<>0),1,0),1)) -> 1 | H7: =IF(OR(G7=0,E7=0),"",C7/E7) -> 1432.0672 | I7: =IF(OR(G7=0,F7=0),"",D7/F7) -> 1411.2036 | J7: =IF(OR(H7="",I7=""),"",IF(H7=0,"",I7/H7-1)) -> -0.014568841 | K7: =IF($B7="","",IFERROR(IF(G7=0,-2E+300,CHOOSE(sortIdx,ROUND(D7,0),IF(J7="",-1E+300,ROUND(-J7,6)),IF(J7="",-1E+300,ROUND(J7,6)))),-1.5E+300)) -> 381024971 | L7: =IF(K7="","",RANK(K7,$K$2:$K$3001,0)+COUNTIF($K$2:K7,K7)-1) -> 2
A8: 하늘포장(주) | B8: =IFERROR(IF(A8="","","="&SUBSTITUTE(SUBSTITUTE(SUBSTITUTE(A8,"~","~~"),"*","~*"),"?","~?")),"") -> =하늘포장(주) | C8: =IF($B8="","",SUMIFS(dAmt,dCust,$B8,dPer,">="&pyFrom,dPer,"<="&pyTo,dAmt,">-1E+300",dFlt1,critFlt1,dFlt2,critFlt2,dFlt3,critFlt3)) -> 183575192 | D8: =IF($B8="","",SUMIFS(dAmt,dCust,$B8,dPer,">="&cyFrom,dPer,"<="&cyTo,dAmt,">-1E+300",dFlt1,critFlt1,dFlt2,critFlt2,dFlt3,critFlt3)) -> 181656007 | E8: =IF($B8="","",SUMIFS(dQty,dCust,$B8,dPer,">="&pyFrom,dPer,"<="&pyTo,dQty,">-1E+300",dFlt1,critFlt1,dFlt2,critFlt2,dFlt3,critFlt3)) -> 126125 | F8: =IF($B8="","",SUMIFS(dQty,dCust,$B8,dPer,">="&cyFrom,dPer,"<="&cyTo,dQty,">-1E+300",dFlt1,critFlt1,dFlt2,critFlt2,dFlt3,critFlt3)) -> 125375 | G8: =IF($B8="",0,IFERROR(IF(OR(C8<>0,D8<>0,E8<>0,F8<>0),1,0),1)) -> 1 | H8: =IF(OR(G8=0,E8=0),"",C8/E8) -> 1455.502 | I8: =IF(OR(G8=0,F8=0),"",D8/F8) -> 1448.9014 | J8: =IF(OR(H8="",I8=""),"",IF(H8=0,"",I8/H8-1)) -> -0.0045349754 | K8: =IF($B8="","",IFERROR(IF(G8=0,-2E+300,CHOOSE(sortIdx,ROUND(D8,0),IF(J8="",-1E+300,ROUND(-J8,6)),IF(J8="",-1E+300,ROUND(J8,6)))),-1.5E+300)) -> 181656007 | L8: =IF(K8="","",RANK(K8,$K$2:$K$3001,0)+COUNTIF($K$2:K8,K8)-1) -> 13 | P8: 정렬 옵션 | Q8: 당해 매출액 큰 순
A9: 한울몰드 | B9: =IFERROR(IF(A9="","","="&SUBSTITUTE(SUBSTITUTE(SUBSTITUTE(A9,"~","~~"),"*","~*"),"?","~?")),"") -> =한울몰드 | C9: =IF($B9="","",SUMIFS(dAmt,dCust,$B9,dPer,">="&pyFrom,dPer,"<="&pyTo,dAmt,">-1E+300",dFlt1,critFlt1,dFlt2,critFlt2,dFlt3,critFlt3)) -> 149086313 | D9: =IF($B9="","",SUMIFS(dAmt,dCust,$B9,dPer,">="&cyFrom,dPer,"<="&cyTo,dAmt,">-1E+300",dFlt1,critFlt1,dFlt2,critFlt2,dFlt3,critFlt3)) -> 189912249 | E9: =IF($B9="","",SUMIFS(dQty,dCust,$B9,dPer,">="&pyFrom,dPer,"<="&pyTo,dQty,">-1E+300",dFlt1,critFlt1,dFlt2,critFlt2,dFlt3,critFlt3)) -> 66500 | F9: =IF($B9="","",SUMIFS(dQty,dCust,$B9,dPer,">="&cyFrom,dPer,"<="&cyTo,dQty,">-1E+300",dFlt1,critFlt1,dFlt2,critFlt2,dFlt3,critFlt3)) -> 80775 | G9: =IF($B9="",0,IFERROR(IF(OR(C9<>0,D9<>0,E9<>0,F9<>0),1,0),1)) -> 1 | H9: =IF(OR(G9=0,E9=0),"",C9/E9) -> 2241.8994 | I9: =IF(OR(G9=0,F9=0),"",D9/F9) -> 2351.1266 | J9: =IF(OR(H9="",I9=""),"",IF(H9=0,"",I9/H9-1)) -> 0.048720798 | K9: =IF($B9="","",IFERROR(IF(G9=0,-2E+300,CHOOSE(sortIdx,ROUND(D9,0),IF(J9="",-1E+300,ROUND(-J9,6)),IF(J9="",-1E+300,ROUND(J9,6)))),-1.5E+300)) -> 189912249 | L9: =IF(K9="","",RANK(K9,$K$2:$K$3001,0)+COUNTIF($K$2:K9,K9)-1) -> 12 | Q9: ASP 증감률 낮은 순 (하락 먼저)
A10: 누리오토파츠 | B10: =IFERROR(IF(A10="","","="&SUBSTITUTE(SUBSTITUTE(SUBSTITUTE(A10,"~","~~"),"*","~*"),"?","~?")),"") -> =누리오토파츠 | C10: =IF($B10="","",SUMIFS(dAmt,dCust,$B10,dPer,">="&pyFrom,dPer,"<="&pyTo,dAmt,">-1E+300",dFlt1,critFlt1,dFlt2,critFlt2,dFlt3,critFlt3)) -> 209508399 | D10: =IF($B10="","",SUMIFS(dAmt,dCust,$B10,dPer,">="&cyFrom,dPer,"<="&cyTo,dAmt,">-1E+300",dFlt1,critFlt1,dFlt2,critFlt2,dFlt3,critFlt3)) -> 256538685 | E10: =IF($B10="","",SUMIFS(dQty,dCust,$B10,dPer,">="&pyFrom,dPer,"<="&pyTo,dQty,">-1E+300",dFlt1,critFlt1,dFlt2,critFlt2,dFlt3,critFlt3)) -> 69975 | F10: =IF($B10="","",SUMIFS(dQty,dCust,$B10,dPer,">="&cyFrom,dPer,"<="&cyTo,dQty,">-1E+300",dFlt1,critFlt1,dFlt2,critFlt2,dFlt3,critFlt3)) -> 89625 | G10: =IF($B10="",0,IFERROR(IF(OR(C10<>0,D10<>0,E10<>0,F10<>0),1,0),1)) -> 1 | H10: =IF(OR(G10=0,E10=0),"",C10/E10) -> 2994.0464 | I10: =IF(OR(G10=0,F10=0),"",D10/F10) -> 2862.3563 | J10: =IF(OR(H10="",I10=""),"",IF(H10=0,"",I10/H10-1)) -> -0.043983992 | K10: =IF($B10="","",IFERROR(IF(G10=0,-2E+300,CHOOSE(sortIdx,ROUND(D10,0),IF(J10="",-1E+300,ROUND(-J10,6)),IF(J10="",-1E+300,ROUND(J10,6)))),-1.5E+300)) -> 256538685 | L10: =IF(K10="","",RANK(K10,$K$2:$K$3001,0)+COUNTIF($K$2:K10,K10)-1) -> 9 | Q10: ASP 증감률 높은 순 (상승 먼저)
A11: 미르패키징 | B11: =IFERROR(IF(A11="","","="&SUBSTITUTE(SUBSTITUTE(SUBSTITUTE(A11,"~","~~"),"*","~*"),"?","~?")),"") -> =미르패키징 | C11: =IF($B11="","",SUMIFS(dAmt,dCust,$B11,dPer,">="&pyFrom,dPer,"<="&pyTo,dAmt,">-1E+300",dFlt1,critFlt1,dFlt2,critFlt2,dFlt3,critFlt3)) -> 161281094 | D11: =IF($B11="","",SUMIFS(dAmt,dCust,$B11,dPer,">="&cyFrom,dPer,"<="&cyTo,dAmt,">-1E+300",dFlt1,critFlt1,dFlt2,critFlt2,dFlt3,critFlt3)) -> 170175605 | E11: =IF($B11="","",SUMIFS(dQty,dCust,$B11,dPer,">="&pyFrom,dPer,"<="&pyTo,dQty,">-1E+300",dFlt1,critFlt1,dFlt2,critFlt2,dFlt3,critFlt3)) -> 107450 | F11: =IF($B11="","",SUMIFS(dQty,dCust,$B11,dPer,">="&cyFrom,dPer,"<="&cyTo,dQty,">-1E+300",dFlt1,critFlt1,dFlt2,critFlt2,dFlt3,critFlt3)) -> 113000 | G11: =IF($B11="",0,IFERROR(IF(OR(C11<>0,D11<>0,E11<>0,F11<>0),1,0),1)) -> 1 | H11: =IF(OR(G11=0,E11=0),"",C11/E11) -> 1500.9874 | I11: =IF(OR(G11=0,F11=0),"",D11/F11) -> 1505.9788 | J11: =IF(OR(H11="",I11=""),"",IF(H11=0,"",I11/H11-1)) -> 0.0033254278 | K11: =IF($B11="","",IFERROR(IF(G11=0,-2E+300,CHOOSE(sortIdx,ROUND(D11,0),IF(J11="",-1E+300,ROUND(-J11,6)),IF(J11="",-1E+300,ROUND(J11,6)))),-1.5E+300)) -> 170175605 | L11: =IF(K11="","",RANK(K11,$K$2:$K$3001,0)+COUNTIF($K$2:K11,K11)-1) -> 15
A12: 차오름산업 | B12: =IFERROR(IF(A12="","","="&SUBSTITUTE(SUBSTITUTE(SUBSTITUTE(A12,"~","~~"),"*","~*"),"?","~?")),"") -> =차오름산업 | C12: =IF($B12="","",SUMIFS(dAmt,dCust,$B12,dPer,">="&pyFrom,dPer,"<="&pyTo,dAmt,">-1E+300",dFlt1,critFlt1,dFlt2,critFlt2,dFlt3,critFlt3)) -> 80239852 | D12: =IF($B12="","",SUMIFS(dAmt,dCust,$B12,dPer,">="&cyFrom,dPer,"<="&cyTo,dAmt,">-1E+300",dFlt1,critFlt1,dFlt2,critFlt2,dFlt3,critFlt3)) -> 0 | E12: =IF($B12="","",SUMIFS(dQty,dCust,$B12,dPer,">="&pyFrom,dPer,"<="&pyTo,dQty,">-1E+300",dFlt1,critFlt1,dFlt2,critFlt2,dFlt3,critFlt3)) -> 46025 | F12: =IF($B12="","",SUMIFS(dQty,dCust,$B12,dPer,">="&cyFrom,dPer,"<="&cyTo,dQty,">-1E+300",dFlt1,critFlt1,dFlt2,critFlt2,dFlt3,critFlt3)) -> 0 | G12: =IF($B12="",0,IFERROR(IF(OR(C12<>0,D12<>0,E12<>0,F12<>0),1,0),1)) -> 1 | H12: =IF(OR(G12=0,E12=0),"",C12/E12) -> 1743.3971 | I12: =IF(OR(G12=0,F12=0),"",D12/F12) | J12: =IF(OR(H12="",I12=""),"",IF(H12=0,"",I12/H12-1)) | K12: =IF($B12="","",IFERROR(IF(G12=0,-2E+300,CHOOSE(sortIdx,ROUND(D12,0),IF(J12="",-1E+300,ROUND(-J12,6)),IF(J12="",-1E+300,ROUND(J12,6)))),-1.5E+300)) -> 0 | L12: =IF(K12="","",RANK(K12,$K$2:$K$3001,0)+COUNTIF($K$2:K12,K12)-1) -> 22
A13: 토담정공(주) | B13: =IFERROR(IF(A13="","","="&SUBSTITUTE(SUBSTITUTE(SUBSTITUTE(A13,"~","~~"),"*","~*"),"?","~?")),"") -> =토담정공(주) | C13: =IF($B13="","",SUMIFS(dAmt,dCust,$B13,dPer,">="&pyFrom,dPer,"<="&pyTo,dAmt,">-1E+300",dFlt1,critFlt1,dFlt2,critFlt2,dFlt3,critFlt3)) -> 87348746 | D13: =IF($B13="","",SUMIFS(dAmt,dCust,$B13,dPer,">="&cyFrom,dPer,"<="&cyTo,dAmt,">-1E+300",dFlt1,critFlt1,dFlt2,critFlt2,dFlt3,critFlt3)) -> 107714975 | E13: =IF($B13="","",SUMIFS(dQty,dCust,$B13,dPer,">="&pyFrom,dPer,"<="&pyTo,dQty,">-1E+300",dFlt1,critFlt1,dFlt2,critFlt2,dFlt3,critFlt3)) -> 30175 | F13: =IF($B13="","",SUMIFS(dQty,dCust,$B13,dPer,">="&cyFrom,dPer,"<="&cyTo,dQty,">-1E+300",dFlt1,critFlt1,dFlt2,critFlt2,dFlt3,critFlt3)) -> 35775 | G13: =IF($B13="",0,IFERROR(IF(OR(C13<>0,D13<>0,E13<>0,F13<>0),1,0),1)) -> 1 | H13: =IF(OR(G13=0,E13=0),"",C13/E13) -> 2894.7389 | I13: =IF(OR(G13=0,F13=0),"",D13/F13) -> 3010.9008 | J13: =IF(OR(H13="",I13=""),"",IF(H13=0,"",I13/H13-1)) -> 0.040128621 | K13: =IF($B13="","",IFERROR(IF(G13=0,-2E+300,CHOOSE(sortIdx,ROUND(D13,0),IF(J13="",-1E+300,ROUND(-J13,6)),IF(J13="",-1E+300,ROUND(J13,6)))),-1.5E+300)) -> 107714975 | L13: =IF(K13="","",RANK(K13,$K$2:$K$3001,0)+COUNTIF($K$2:K13,K13)-1) -> 18
A14: 다솜케미칼 | B14: =IFERROR(IF(A14="","","="&SUBSTITUTE(SUBSTITUTE(SUBSTITUTE(A14,"~","~~"),"*","~*"),"?","~?")),"") -> =다솜케미칼 | C14: =IF($B14="","",SUMIFS(dAmt,dCust,$B14,dPer,">="&pyFrom,dPer,"<="&pyTo,dAmt,">-1E+300",dFlt1,critFlt1,dFlt2,critFlt2,dFlt3,critFlt3)) -> 235928564 | D14: =IF($B14="","",SUMIFS(dAmt,dCust,$B14,dPer,">="&cyFrom,dPer,"<="&cyTo,dAmt,">-1E+300",dFlt1,critFlt1,dFlt2,critFlt2,dFlt3,critFlt3)) -> 273632570 | E14: =IF($B14="","",SUMIFS(dQty,dCust,$B14,dPer,">="&pyFrom,dPer,"<="&pyTo,dQty,">-1E+300",dFlt1,critFlt1,dFlt2,critFlt2,dFlt3,critFlt3)) -> 69100 | F14: =IF($B14="","",SUMIFS(dQty,dCust,$B14,dPer,">="&cyFrom,dPer,"<="&cyTo,dQty,">-1E+300",dFlt1,critFlt1,dFlt2,critFlt2,dFlt3,critFlt3)) -> 76025 | G14: =IF($B14="",0,IFERROR(IF(OR(C14<>0,D14<>0,E14<>0,F14<>0),1,0),1)) -> 1 | H14: =IF(OR(G14=0,E14=0),"",C14/E14) -> 3414.3063 | I14: =IF(OR(G14=0,F14=0),"",D14/F14) -> 3599.2446 | J14: =IF(OR(H14="",I14=""),"",IF(H14=0,"",I14/H14-1)) -> 0.054165706 | K14: =IF($B14="","",IFERROR(IF(G14=0,-2E+300,CHOOSE(sortIdx,ROUND(D14,0),IF(J14="",-1E+300,ROUND(-J14,6)),IF(J14="",-1E+300,ROUND(J14,6)))),-1.5E+300)) -> 273632570 | L14: =IF(K14="","",RANK(K14,$K$2:$K$3001,0)+COUNTIF($K$2:K14,K14)-1) -> 7
A15: Sinar Plastik (ID) | B15: =IFERROR(IF(A15="","","="&SUBSTITUTE(SUBSTITUTE(SUBSTITUTE(A15,"~","~~"),"*","~*"),"?","~?")),"") -> =Sinar Plastik (ID) | C15: =IF($B15="","",SUMIFS(dAmt,dCust,$B15,dPer,">="&pyFrom,dPer,"<="&pyTo,dAmt,">-1E+300",dFlt1,critFlt1,dFlt2,critFlt2,dFlt3,critFlt3)) -> 421977654 | D15: =IF($B15="","",SUMIFS(dAmt,dCust,$B15,dPer,">="&cyFrom,dPer,"<="&cyTo,dAmt,">-1E+300",dFlt1,critFlt1,dFlt2,critFlt2,dFlt3,critFlt3)) -> 398348378 | E15: =IF($B15="","",SUMIFS(dQty,dCust,$B15,dPer,">="&pyFrom,dPer,"<="&pyTo,dQty,">-1E+300",dFlt1,critFlt1,dFlt2,critFlt2,dFlt3,critFlt3)) -> 253975 | F15: =IF($B15="","",SUMIFS(dQty,dCust,$B15,dPer,">="&cyFrom,dPer,"<="&cyTo,dQty,">-1E+300",dFlt1,critFlt1,dFlt2,critFlt2,dFlt3,critFlt3)) -> 239600 | G15: =IF($B15="",0,IFERROR(IF(OR(C15<>0,D15<>0,E15<>0,F15<>0),1,0),1)) -> 1 | H15: =IF(OR(G15=0,E15=0),"",C15/E15) -> 1661.4929 | I15: =IF(OR(G15=0,F15=0),"",D15/F15) -> 1662.5558 | J15: =IF(OR(H15="",I15=""),"",IF(H15=0,"",I15/H15-1)) -> 0.00063975929 | K15: =IF($B15="","",IFERROR(IF(G15=0,-2E+300,CHOOSE(sortIdx,ROUND(D15,0),IF(J15="",-1E+300,ROUND(-J15,6)),IF(J15="",-1E+300,ROUND(J15,6)))),-1.5E+300)) -> 398348378 | L15: =IF(K15="","",RANK(K15,$K$2:$K$3001,0)+COUNTIF($K$2:K15,K15)-1) -> 1
A16: 바른물산 | B16: =IFERROR(IF(A16="","","="&SUBSTITUTE(SUBSTITUTE(SUBSTITUTE(A16,"~","~~"),"*","~*"),"?","~?")),"") -> =바른물산 | C16: =IF($B16="","",SUMIFS(dAmt,dCust,$B16,dPer,">="&pyFrom,dPer,"<="&pyTo,dAmt,">-1E+300",dFlt1,critFlt1,dFlt2,critFlt2,dFlt3,critFlt3)) -> 190701333 | D16: =IF($B16="","",SUMIFS(dAmt,dCust,$B16,dPer,">="&cyFrom,dPer,"<="&cyTo,dAmt,">-1E+300",dFlt1,critFlt1,dFlt2,critFlt2,dFlt3,critFlt3)) -> 115220314 | E16: =IF($B16="","",SUMIFS(dQty,dCust,$B16,dPer,">="&pyFrom,dPer,"<="&pyTo,dQty,">-1E+300",dFlt1,critFlt1,dFlt2,critFlt2,dFlt3,critFlt3)) -> 135350 | F16: =IF($B16="","",SUMIFS(dQty,dCust,$B16,dPer,">="&cyFrom,dPer,"<="&cyTo,dQty,">-1E+300",dFlt1,critFlt1,dFlt2,critFlt2,dFlt3,critFlt3)) -> 84175 | G16: =IF($B16="",0,IFERROR(IF(OR(C16<>0,D16<>0,E16<>0,F16<>0),1,0),1)) -> 1 | H16: =IF(OR(G16=0,E16=0),"",C16/E16) -> 1408.9496 | I16: =IF(OR(G16=0,F16=0),"",D16/F16) -> 1368.8187 | J16: =IF(OR(H16="",I16=""),"",IF(H16=0,"",I16/H16-1)) -> -0.028482874 | K16: =IF($B16="","",IFERROR(IF(G16=0,-2E+300,CHOOSE(sortIdx,ROUND(D16,0),IF(J16="",-1E+300,ROUND(-J16,6)),IF(J16="",-1E+300,ROUND(J16,6)))),-1.5E+300)) -> 115220314 | L16: =IF(K16="","",RANK(K16,$K$2:$K$3001,0)+COUNTIF($K$2:K16,K16)-1) -> 17
A17: 파란하이텍 | B17: =IFERROR(IF(A17="","","="&SUBSTITUTE(SUBSTITUTE(SUBSTITUTE(A17,"~","~~"),"*","~*"),"?","~?")),"") -> =파란하이텍 | C17: =IF($B17="","",SUMIFS(dAmt,dCust,$B17,dPer,">="&pyFrom,dPer,"<="&pyTo,dAmt,">-1E+300",dFlt1,critFlt1,dFlt2,critFlt2,dFlt3,critFlt3)) -> 222484560 | D17: =IF($B17="","",SUMIFS(dAmt,dCust,$B17,dPer,">="&cyFrom,dPer,"<="&cyTo,dAmt,">-1E+300",dFlt1,critFlt1,dFlt2,critFlt2,dFlt3,critFlt3)) -> 294634344 | E17: =IF($B17="","",SUMIFS(dQty,dCust,$B17,dPer,">="&pyFrom,dPer,"<="&pyTo,dQty,">-1E+300",dFlt1,critFlt1,dFlt2,critFlt2,dFlt3,critFlt3)) -> 56725 | F17: =IF($B17="","",SUMIFS(dQty,dCust,$B17,dPer,">="&cyFrom,dPer,"<="&cyTo,dQty,">-1E+300",dFlt1,critFlt1,dFlt2,critFlt2,dFlt3,critFlt3)) -> 76275 | G17: =IF($B17="",0,IFERROR(IF(OR(C17<>0,D17<>0,E17<>0,F17<>0),1,0),1)) -> 1 | H17: =IF(OR(G17=0,E17=0),"",C17/E17) -> 3922.1606 | I17: =IF(OR(G17=0,F17=0),"",D17/F17) -> 3862.7905 | J17: =IF(OR(H17="",I17=""),"",IF(H17=0,"",I17/H17-1)) -> -0.015137095 | K17: =IF($B17="","",IFERROR(IF(G17=0,-2E+300,CHOOSE(sortIdx,ROUND(D17,0),IF(J17="",-1E+300,ROUND(-J17,6)),IF(J17="",-1E+300,ROUND(J17,6)))),-1.5E+300)) -> 294634344 | L17: =IF(K17="","",RANK(K17,$K$2:$K$3001,0)+COUNTIF($K$2:K17,K17)-1) -> 5
A18: 라온테크(주) | B18: =IFERROR(IF(A18="","","="&SUBSTITUTE(SUBSTITUTE(SUBSTITUTE(A18,"~","~~"),"*","~*"),"?","~?")),"") -> =라온테크(주) | C18: =IF($B18="","",SUMIFS(dAmt,dCust,$B18,dPer,">="&pyFrom,dPer,"<="&pyTo,dAmt,">-1E+300",dFlt1,critFlt1,dFlt2,critFlt2,dFlt3,critFlt3)) -> 238900061 | D18: =IF($B18="","",SUMIFS(dAmt,dCust,$B18,dPer,">="&cyFrom,dPer,"<="&cyTo,dAmt,">-1E+300",dFlt1,critFlt1,dFlt2,critFlt2,dFlt3,critFlt3)) -> 284758055 | E18: =IF($B18="","",SUMIFS(dQty,dCust,$B18,dPer,">="&pyFrom,dPer,"<="&pyTo,dQty,">-1E+300",dFlt1,critFlt1,dFlt2,critFlt2,dFlt3,critFlt3)) -> 89625 | F18: =IF($B18="","",SUMIFS(dQty,dCust,$B18,dPer,">="&cyFrom,dPer,"<="&cyTo,dQty,">-1E+300",dFlt1,critFlt1,dFlt2,critFlt2,dFlt3,critFlt3)) -> 109325 | G18: =IF($B18="",0,IFERROR(IF(OR(C18<>0,D18<>0,E18<>0,F18<>0),1,0),1)) -> 1 | H18: =IF(OR(G18=0,E18=0),"",C18/E18) -> 2665.5516 | I18: =IF(OR(G18=0,F18=0),"",D18/F18) -> 2604.6929 | J18: =IF(OR(H18="",I18=""),"",IF(H18=0,"",I18/H18-1)) -> -0.022831542 | K18: =IF($B18="","",IFERROR(IF(G18=0,-2E+300,CHOOSE(sortIdx,ROUND(D18,0),IF(J18="",-1E+300,ROUND(-J18,6)),IF(J18="",-1E+300,ROUND(J18,6)))),-1.5E+300)) -> 284758055 | L18: =IF(K18="","",RANK(K18,$K$2:$K$3001,0)+COUNTIF($K$2:K18,K18)-1) -> 6
A19: 나래산업(주) | B19: =IFERROR(IF(A19="","","="&SUBSTITUTE(SUBSTITUTE(SUBSTITUTE(A19,"~","~~"),"*","~*"),"?","~?")),"") -> =나래산업(주) | C19: =IF($B19="","",SUMIFS(dAmt,dCust,$B19,dPer,">="&pyFrom,dPer,"<="&pyTo,dAmt,">-1E+300",dFlt1,critFlt1,dFlt2,critFlt2,dFlt3,critFlt3)) -> 261543968 | D19: =IF($B19="","",SUMIFS(dAmt,dCust,$B19,dPer,">="&cyFrom,dPer,"<="&cyTo,dAmt,">-1E+300",dFlt1,critFlt1,dFlt2,critFlt2,dFlt3,critFlt3)) -> 331743492 | E19: =IF($B19="","",SUMIFS(dQty,dCust,$B19,dPer,">="&pyFrom,dPer,"<="&pyTo,dQty,">-1E+300",dFlt1,critFlt1,dFlt2,critFlt2,dFlt3,critFlt3)) -> 173850 | F19: =IF($B19="","",SUMIFS(dQty,dCust,$B19,dPer,">="&cyFrom,dPer,"<="&cyTo,dQty,">-1E+300",dFlt1,critFlt1,dFlt2,critFlt2,dFlt3,critFlt3)) -> 225450 | G19: =IF($B19="",0,IFERROR(IF(OR(C19<>0,D19<>0,E19<>0,F19<>0),1,0),1)) -> 1 | H19: =IF(OR(G19=0,E19=0),"",C19/E19) -> 1504.4232 | I19: =IF(OR(G19=0,F19=0),"",D19/F19) -> 1471.4726 | J19: =IF(OR(H19="",I19=""),"",IF(H19=0,"",I19/H19-1)) -> -0.021902477 | K19: =IF($B19="","",IFERROR(IF(G19=0,-2E+300,CHOOSE(sortIdx,ROUND(D19,0),IF(J19="",-1E+300,ROUND(-J19,6)),IF(J19="",-1E+300,ROUND(J19,6)))),-1.5E+300)) -> 331743492 | L19: =IF(K19="","",RANK(K19,$K$2:$K$3001,0)+COUNTIF($K$2:K19,K19)-1) -> 4
A20: 마루정밀 | B20: =IFERROR(IF(A20="","","="&SUBSTITUTE(SUBSTITUTE(SUBSTITUTE(A20,"~","~~"),"*","~*"),"?","~?")),"") -> =마루정밀 | C20: =IF($B20="","",SUMIFS(dAmt,dCust,$B20,dPer,">="&pyFrom,dPer,"<="&pyTo,dAmt,">-1E+300",dFlt1,critFlt1,dFlt2,critFlt2,dFlt3,critFlt3)) -> 129460516 | D20: =IF($B20="","",SUMIFS(dAmt,dCust,$B20,dPer,">="&cyFrom,dPer,"<="&cyTo,dAmt,">-1E+300",dFlt1,critFlt1,dFlt2,critFlt2,dFlt3,critFlt3)) -> 172224113 | E20: =IF($B20="","",SUMIFS(dQty,dCust,$B20,dPer,">="&pyFrom,dPer,"<="&pyTo,dQty,">-1E+300",dFlt1,critFlt1,dFlt2,critFlt2,dFlt3,critFlt3)) -> 34550 | F20: =IF($B20="","",SUMIFS(dQty,dCust,$B20,dPer,">="&cyFrom,dPer,"<="&cyTo,dQty,">-1E+300",dFlt1,critFlt1,dFlt2,critFlt2,dFlt3,critFlt3)) -> 44775 | G20: =IF($B20="",0,IFERROR(IF(OR(C20<>0,D20<>0,E20<>0,F20<>0),1,0),1)) -> 1 | H20: =IF(OR(G20=0,E20=0),"",C20/E20) -> 3747.0482 | I20: =IF(OR(G20=0,F20=0),"",D20/F20) -> 3846.4347 | J20: =IF(OR(H20="",I20=""),"",IF(H20=0,"",I20/H20-1)) -> 0.026523935 | K20: =IF($B20="","",IFERROR(IF(G20=0,-2E+300,CHOOSE(sortIdx,ROUND(D20,0),IF(J20="",-1E+300,ROUND(-J20,6)),IF(J20="",-1E+300,ROUND(J20,6)))),-1.5E+300)) -> 172224113 | L20: =IF(K20="","",RANK(K20,$K$2:$K$3001,0)+COUNTIF($K$2:K20,K20)-1) -> 14
A21: 아름화학(주) | B21: =IFERROR(IF(A21="","","="&SUBSTITUTE(SUBSTITUTE(SUBSTITUTE(A21,"~","~~"),"*","~*"),"?","~?")),"") -> =아름화학(주) | C21: =IF($B21="","",SUMIFS(dAmt,dCust,$B21,dPer,">="&pyFrom,dPer,"<="&pyTo,dAmt,">-1E+300",dFlt1,critFlt1,dFlt2,critFlt2,dFlt3,critFlt3)) -> 296920992 | D21: =IF($B21="","",SUMIFS(dAmt,dCust,$B21,dPer,">="&cyFrom,dPer,"<="&cyTo,dAmt,">-1E+300",dFlt1,critFlt1,dFlt2,critFlt2,dFlt3,critFlt3)) -> 270865712 | E21: =IF($B21="","",SUMIFS(dQty,dCust,$B21,dPer,">="&pyFrom,dPer,"<="&pyTo,dQty,">-1E+300",dFlt1,critFlt1,dFlt2,critFlt2,dFlt3,critFlt3)) -> 189100 | F21: =IF($B21="","",SUMIFS(dQty,dCust,$B21,dPer,">="&cyFrom,dPer,"<="&cyTo,dQty,">-1E+300",dFlt1,critFlt1,dFlt2,critFlt2,dFlt3,critFlt3)) -> 173250 | G21: =IF($B21="",0,IFERROR(IF(OR(C21<>0,D21<>0,E21<>0,F21<>0),1,0),1)) -> 1 | H21: =IF(OR(G21=0,E21=0),"",C21/E21) -> 1570.1798 | I21: =IF(OR(G21=0,F21=0),"",D21/F21) -> 1563.4385 | J21: =IF(OR(H21="",I21=""),"",IF(H21=0,"",I21/H21-1)) -> -0.0042933324 | K21: =IF($B21="","",IFERROR(IF(G21=0,-2E+300,CHOOSE(sortIdx,ROUND(D21,0),IF(J21="",-1E+300,ROUND(-J21,6)),IF(J21="",-1E+300,ROUND(J21,6)))),-1.5E+300)) -> 270865712 | L21: =IF(K21="","",RANK(K21,$K$2:$K$3001,0)+COUNTIF($K$2:K21,K21)-1) -> 8
A22: 든솔케이스 | B22: =IFERROR(IF(A22="","","="&SUBSTITUTE(SUBSTITUTE(SUBSTITUTE(A22,"~","~~"),"*","~*"),"?","~?")),"") -> =든솔케이스 | C22: =IF($B22="","",SUMIFS(dAmt,dCust,$B22,dPer,">="&pyFrom,dPer,"<="&pyTo,dAmt,">-1E+300",dFlt1,critFlt1,dFlt2,critFlt2,dFlt3,critFlt3)) -> 0 | D22: =IF($B22="","",SUMIFS(dAmt,dCust,$B22,dPer,">="&cyFrom,dPer,"<="&cyTo,dAmt,">-1E+300",dFlt1,critFlt1,dFlt2,critFlt2,dFlt3,critFlt3)) -> 83558929 | E22: =IF($B22="","",SUMIFS(dQty,dCust,$B22,dPer,">="&pyFrom,dPer,"<="&pyTo,dQty,">-1E+300",dFlt1,critFlt1,dFlt2,critFlt2,dFlt3,critFlt3)) -> 0 | F22: =IF($B22="","",SUMIFS(dQty,dCust,$B22,dPer,">="&cyFrom,dPer,"<="&cyTo,dQty,">-1E+300",dFlt1,critFlt1,dFlt2,critFlt2,dFlt3,critFlt3)) -> 31550 | G22: =IF($B22="",0,IFERROR(IF(OR(C22<>0,D22<>0,E22<>0,F22<>0),1,0),1)) -> 1 | H22: =IF(OR(G22=0,E22=0),"",C22/E22) | I22: =IF(OR(G22=0,F22=0),"",D22/F22) -> 2648.4605 | J22: =IF(OR(H22="",I22=""),"",IF(H22=0,"",I22/H22-1)) | K22: =IF($B22="","",IFERROR(IF(G22=0,-2E+300,CHOOSE(sortIdx,ROUND(D22,0),IF(J22="",-1E+300,ROUND(-J22,6)),IF(J22="",-1E+300,ROUND(J22,6)))),-1.5E+300)) -> 83558929 | L22: =IF(K22="","",RANK(K22,$K$2:$K$3001,0)+COUNTIF($K$2:K22,K22)-1) -> 21
A23: Hanoi Molding (VN) | B23: =IFERROR(IF(A23="","","="&SUBSTITUTE(SUBSTITUTE(SUBSTITUTE(A23,"~","~~"),"*","~*"),"?","~?")),"") -> =Hanoi Molding (VN) | C23: =IF($B23="","",SUMIFS(dAmt,dCust,$B23,dPer,">="&pyFrom,dPer,"<="&pyTo,dAmt,">-1E+300",dFlt1,critFlt1,dFlt2,critFlt2,dFlt3,critFlt3)) -> 0 | D23: =IF($B23="","",SUMIFS(dAmt,dCust,$B23,dPer,">="&cyFrom,dPer,"<="&cyTo,dAmt,">-1E+300",dFlt1,critFlt1,dFlt2,critFlt2,dFlt3,critFlt3)) -> 225489827 | E23: =IF($B23="","",SUMIFS(dQty,dCust,$B23,dPer,">="&pyFrom,dPer,"<="&pyTo,dQty,">-1E+300",dFlt1,critFlt1,dFlt2,critFlt2,dFlt3,critFlt3)) -> 0 | F23: =IF($B23="","",SUMIFS(dQty,dCust,$B23,dPer,">="&cyFrom,dPer,"<="&cyTo,dQty,">-1E+300",dFlt1,critFlt1,dFlt2,critFlt2,dFlt3,critFlt3)) -> 103975 | G23: =IF($B23="",0,IFERROR(IF(OR(C23<>0,D23<>0,E23<>0,F23<>0),1,0),1)) -> 1 | H23: =IF(OR(G23=0,E23=0),"",C23/E23) | I23: =IF(OR(G23=0,F23=0),"",D23/F23) -> 2168.6927 | J23: =IF(OR(H23="",I23=""),"",IF(H23=0,"",I23/H23-1)) | K23: =IF($B23="","",IFERROR(IF(G23=0,-2E+300,CHOOSE(sortIdx,ROUND(D23,0),IF(J23="",-1E+300,ROUND(-J23,6)),IF(J23="",-1E+300,ROUND(J23,6)))),-1.5E+300)) -> 225489827 | L23: =IF(K23="","",RANK(K23,$K$2:$K$3001,0)+COUNTIF($K$2:K23,K23)-1) -> 10
B24: =IFERROR(IF(A24="","","="&SUBSTITUTE(SUBSTITUTE(SUBSTITUTE(A24,"~","~~"),"*","~*"),"?","~?")),"") | C24: =IF($B24="","",SUMIFS(dAmt,dCust,$B24,dPer,">="&pyFrom,dPer,"<="&pyTo,dAmt,">-1E+300",dFlt1,critFlt1,dFlt2,critFlt2,dFlt3,critFlt3)) | D24: =IF($B24="","",SUMIFS(dAmt,dCust,$B24,dPer,">="&cyFrom,dPer,"<="&cyTo,dAmt,">-1E+300",dFlt1,critFlt1,dFlt2,critFlt2,dFlt3,critFlt3)) | E24: =IF($B24="","",SUMIFS(dQty,dCust,$B24,dPer,">="&pyFrom,dPer,"<="&pyTo,dQty,">-1E+300",dFlt1,critFlt1,dFlt2,critFlt2,dFlt3,critFlt3)) | F24: =IF($B24="","",SUMIFS(dQty,dCust,$B24,dPer,">="&cyFrom,dPer,"<="&cyTo,dQty,">-1E+300",dFlt1,critFlt1,dFlt2,critFlt2,dFlt3,critFlt3)) | G24: =IF($B24="",0,IFERROR(IF(OR(C24<>0,D24<>0,E24<>0,F24<>0),1,0),1)) -> 0 | H24: =IF(OR(G24=0,E24=0),"",C24/E24) | I24: =IF(OR(G24=0,F24=0),"",D24/F24) | J24: =IF(OR(H24="",I24=""),"",IF(H24=0,"",I24/H24-1)) | K24: =IF($B24="","",IFERROR(IF(G24=0,-2E+300,CHOOSE(sortIdx,ROUND(D24,0),IF(J24="",-1E+300,ROUND(-J24,6)),IF(J24="",-1E+300,ROUND(J24,6)))),-1.5E+300)) | L24: =IF(K24="","",RANK(K24,$K$2:$K$3001,0)+COUNTIF($K$2:K24,K24)-1)
B25: =IFERROR(IF(A25="","","="&SUBSTITUTE(SUBSTITUTE(SUBSTITUTE(A25,"~","~~"),"*","~*"),"?","~?")),"") | C25: =IF($B25="","",SUMIFS(dAmt,dCust,$B25,dPer,">="&pyFrom,dPer,"<="&pyTo,dAmt,">-1E+300",dFlt1,critFlt1,dFlt2,critFlt2,dFlt3,critFlt3)) | D25: =IF($B25="","",SUMIFS(dAmt,dCust,$B25,dPer,">="&cyFrom,dPer,"<="&cyTo,dAmt,">-1E+300",dFlt1,critFlt1,dFlt2,critFlt2,dFlt3,critFlt3)) | E25: =IF($B25="","",SUMIFS(dQty,dCust,$B25,dPer,">="&pyFrom,dPer,"<="&pyTo,dQty,">-1E+300",dFlt1,critFlt1,dFlt2,critFlt2,dFlt3,critFlt3)) | F25: =IF($B25="","",SUMIFS(dQty,dCust,$B25,dPer,">="&cyFrom,dPer,"<="&cyTo,dQty,">-1E+300",dFlt1,critFlt1,dFlt2,critFlt2,dFlt3,critFlt3)) | G25: =IF($B25="",0,IFERROR(IF(OR(C25<>0,D25<>0,E25<>0,F25<>0),1,0),1)) -> 0 | H25: =IF(OR(G25=0,E25=0),"",C25/E25) | I25: =IF(OR(G25=0,F25=0),"",D25/F25) | J25: =IF(OR(H25="",I25=""),"",IF(H25=0,"",I25/H25-1)) | K25: =IF($B25="","",IFERROR(IF(G25=0,-2E+300,CHOOSE(sortIdx,ROUND(D25,0),IF(J25="",-1E+300,ROUND(-J25,6)),IF(J25="",-1E+300,ROUND(J25,6)))),-1.5E+300)) | L25: =IF(K25="","",RANK(K25,$K$2:$K$3001,0)+COUNTIF($K$2:K25,K25)-1)
B26: =IFERROR(IF(A26="","","="&SUBSTITUTE(SUBSTITUTE(SUBSTITUTE(A26,"~","~~"),"*","~*"),"?","~?")),"") | C26: =IF($B26="","",SUMIFS(dAmt,dCust,$B26,dPer,">="&pyFrom,dPer,"<="&pyTo,dAmt,">-1E+300",dFlt1,critFlt1,dFlt2,critFlt2,dFlt3,critFlt3)) | D26: =IF($B26="","",SUMIFS(dAmt,dCust,$B26,dPer,">="&cyFrom,dPer,"<="&cyTo,dAmt,">-1E+300",dFlt1,critFlt1,dFlt2,critFlt2,dFlt3,critFlt3)) | E26: =IF($B26="","",SUMIFS(dQty,dCust,$B26,dPer,">="&pyFrom,dPer,"<="&pyTo,dQty,">-1E+300",dFlt1,critFlt1,dFlt2,critFlt2,dFlt3,critFlt3)) | F26: =IF($B26="","",SUMIFS(dQty,dCust,$B26,dPer,">="&cyFrom,dPer,"<="&cyTo,dQty,">-1E+300",dFlt1,critFlt1,dFlt2,critFlt2,dFlt3,critFlt3)) | G26: =IF($B26="",0,IFERROR(IF(OR(C26<>0,D26<>0,E26<>0,F26<>0),1,0),1)) -> 0 | H26: =IF(OR(G26=0,E26=0),"",C26/E26) | I26: =IF(OR(G26=0,F26=0),"",D26/F26) | J26: =IF(OR(H26="",I26=""),"",IF(H26=0,"",I26/H26-1)) | K26: =IF($B26="","",IFERROR(IF(G26=0,-2E+300,CHOOSE(sortIdx,ROUND(D26,0),IF(J26="",-1E+300,ROUND(-J26,6)),IF(J26="",-1E+300,ROUND(J26,6)))),-1.5E+300)) | L26: =IF(K26="","",RANK(K26,$K$2:$K$3001,0)+COUNTIF($K$2:K26,K26)-1)
B27: =IFERROR(IF(A27="","","="&SUBSTITUTE(SUBSTITUTE(SUBSTITUTE(A27,"~","~~"),"*","~*"),"?","~?")),"") | C27: =IF($B27="","",SUMIFS(dAmt,dCust,$B27,dPer,">="&pyFrom,dPer,"<="&pyTo,dAmt,">-1E+300",dFlt1,critFlt1,dFlt2,critFlt2,dFlt3,critFlt3)) | D27: =IF($B27="","",SUMIFS(dAmt,dCust,$B27,dPer,">="&cyFrom,dPer,"<="&cyTo,dAmt,">-1E+300",dFlt1,critFlt1,dFlt2,critFlt2,dFlt3,critFlt3)) | E27: =IF($B27="","",SUMIFS(dQty,dCust,$B27,dPer,">="&pyFrom,dPer,"<="&pyTo,dQty,">-1E+300",dFlt1,critFlt1,dFlt2,critFlt2,dFlt3,critFlt3)) | F27: =IF($B27="","",SUMIFS(dQty,dCust,$B27,dPer,">="&cyFrom,dPer,"<="&cyTo,dQty,">-1E+300",dFlt1,critFlt1,dFlt2,critFlt2,dFlt3,critFlt3)) | G27: =IF($B27="",0,IFERROR(IF(OR(C27<>0,D27<>0,E27<>0,F27<>0),1,0),1)) -> 0 | H27: =IF(OR(G27=0,E27=0),"",C27/E27) | I27: =IF(OR(G27=0,F27=0),"",D27/F27) | J27: =IF(OR(H27="",I27=""),"",IF(H27=0,"",I27/H27-1)) | K27: =IF($B27="","",IFERROR(IF(G27=0,-2E+300,CHOOSE(sortIdx,ROUND(D27,0),IF(J27="",-1E+300,ROUND(-J27,6)),IF(J27="",-1E+300,ROUND(J27,6)))),-1.5E+300)) | L27: =IF(K27="","",RANK(K27,$K$2:$K$3001,0)+COUNTIF($K$2:K27,K27)-1)
